Workbook

Sheet Gantt
A1: CJA Customer Insight Backend Views – Project Plan
A2: Project start (Monday): | C2: 46300 | D2: Go-live: | E2: =H66 -> 46350
A4: ID | B4: Phase / Task | C4: Owner (role) | D4: Type | E4: Start offset (wd) | F4: Duration (wd) | G4: Start | H4: End | I4: Depends on | J4: Status | K4: % Complete | L4: W1 | M4: W2 | N4: W3 | O4: W4 | P4: W5 | Q4: W6 | R4: W7 | S4: W8
L5: =$C$2+0 -> 46300 | M5: =$C$2+7 -> 46307 | N5: =$C$2+14 -> 46314 | O5: =$C$2+21 -> 46321 | P5: =$C$2+28 -> 46328 | Q5: =$C$2+35 -> 46335 | R5: =$C$2+42 -> 46342 | S5: =$C$2+49 -> 46349
A6: 0 | B6: Mobilisation & Governance | D6: Phase | E6: =MIN(E7:E10) -> 0 | F6: =NETWORKDAYS(G6,H6) -> 7 | G6: =MIN(G7:G10) -> 46300 | H6: =MAX(H7:H10) -> 46308 | K6: =IF(SUMIF(D7:D10,"Task",F7:F10)=0,0,SUMPRODUCT((D7:D10="Task")*F7:F10*K7:K10)/SUMIF(D7:D10,"Task",F7:F10)) -> 0
A7: 0.1 | B7: Kickoff, stakeholder map, RACI | C7: PM | D7: Task | E7: 0 | F7: 2 | G7: =WORKDAY($C$2,E7) -> 46300 | H7: =WORKDAY(G7,F7-1) -> 46301 | J7: Not started | K7: 0
A8: 0.2 | B8: Databricks workspace / Unity Catalog + source-system access requests | C8: Platform / DevOps | D8: Task | E8: 0 | F8: 7 | G8: =WORKDAY($C$2,E8) -> 46300 | H8: =WORKDAY(G8,F8-1) -> 46308 | I8: 0.1 | J8: Not started | K8: 0
A9: 0.3 | B9: Governance cadence set up (weekly status, steering) | C9: PM | D9: Task | E9: 2 | F9: 3 | G9: =WORKDAY($C$2,E9) -> 46302 | H9: =WORKDAY(G9,F9-1) -> 46304 | I9: 0.1 | J9: Not started | K9: 0
A10: M0 | B10: Kickoff complete | C10: PM | D10: Milestone | E10: 1 | F10: 0 | G10: =WORKDAY($C$2,E10) -> 46301 | H10: =G10 -> 46301 | I10: 0.1 | J10: Not started | K10: 0 | L10: =IF(AND($G10>=L$5,$G10<=L$5+4),"◆","") -> ◆ | M10: =IF(AND($G10>=M$5,$G10<=M$5+4),"◆","") | N10: =IF(AND($G10>=N$5,$G10<=N$5+4),"◆","") | O10: =IF(AND($G10>=O$5,$G10<=O$5+4),"◆","") | P10: =IF(AND($G10>=P$5,$G10<=P$5+4),"◆","") | Q10: =IF(AND($G10>=Q$5,$G10<=Q$5+4),"◆","") | R10: =IF(AND($G10>=R$5,$G10<=R$5+4),"◆","") | S10: =IF(AND($G10>=S$5,$G10<=S$5+4),"◆","")
A11: 1 | B11: Requirements & Data Analysis (iterative, by batch) | D11: Phase | E11: =MIN(E12:E23) -> 0 | F11: =NETWORKDAYS(G11,H11) -> 20 | G11: =MIN(G12:G23) -> 46300 | H11: =MAX(H12:H23) -> 46325 | K11: =IF(SUMIF(D12:D23,"Task",F12:F23)=0,0,SUMPRODUCT((D12:D23="Task")*F12:F23*K12:K23)/SUMIF(D12:D23,"Task",F12:F23)) -> 0
A12: 1.1 | B12: Batch A (~20 attrs, internal sources) – requirements & definitions | C12: BA / Business SME | D12: Task | E12: 0 | F12: 5 | G12: =WORKDAY($C$2,E12) -> 46300 | H12: =WORKDAY(G12,F12-1) -> 46304 | I12: 0.1 | J12: Not started | K12: 0
A13: 1.2 | B13: Batch A – source mapping, profiling, DQ assessment | C13: Data Analyst | D13: Task | E13: 2 | F13: 8 | G13: =WORKDAY($C$2,E13) -> 46302 | H13: =WORKDAY(G13,F13-1) -> 46311 | I13: 1.1 | J13: Not started | K13: 0
A14: M1A | B14: Batch A requirements + analysis sign-off | C14: Business SME | D14: Milestone | E14: 9 | F14: 0 | G14: =WORKDAY($C$2,E14) -> 46311 | H14: =G14 -> 46311 | I14: 1.2 | J14: Not started | K14: 0 | L14: =IF(AND($G14>=L$5,$G14<=L$5+4),"◆","") | M14: =IF(AND($G14>=M$5,$G14<=M$5+4),"◆","") -> ◆ | N14: =IF(AND($G14>=N$5,$G14<=N$5+4),"◆","") | O14: =IF(AND($G14>=O$5,$G14<=O$5+4),"◆","") | P14: =IF(AND($G14>=P$5,$G14<=P$5+4),"◆","") | Q14: =IF(AND($G14>=Q$5,$G14<=Q$5+4),"◆","") | R14: =IF(AND($G14>=R$5,$G14<=R$5+4),"◆","") | S14: =IF(AND($G14>=S$5,$G14<=S$5+4),"◆","")
A15: 1.3 | B15: Batch B (~20 attrs, derived / multi-source) – requirements | C15: BA / Business SME | D15: Task | E15: 3 | F15: 7 | G15: =WORKDAY($C$2,E15) -> 46303 | H15: =WORKDAY(G15,F15-1) -> 46311 | I15: 0.1 | J15: Not started | K15: 0
A16: 1.4 | B16: Batch B – source mapping, profiling, DQ assessment | C16: Data Analyst | D16: Task | E16: 5 | F16: 10 | G16: =WORKDAY($C$2,E16) -> 46307 | H16: =WORKDAY(G16,F16-1) -> 46318 | I16: 1.3 | J16: Not started | K16: 0
A17: M1B | B17: Batch B requirements + analysis sign-off | C17: Business SME | D17: Milestone | E17: 14 | F17: 0 | G17: =WORKDAY($C$2,E17) -> 46318 | H17: =G17 -> 46318 | I17: 1.4 | J17: Not started | K17: 0 | L17: =IF(AND($G17>=L$5,$G17<=L$5+4),"◆","") | M17: =IF(AND($G17>=M$5,$G17<=M$5+4),"◆","") | N17: =IF(AND($G17>=N$5,$G17<=N$5+4),"◆","") -> ◆ | O17: =IF(AND($G17>=O$5,$G17<=O$5+4),"◆","") | P17: =IF(AND($G17>=P$5,$G17<=P$5+4),"◆","") | Q17: =IF(AND($G17>=Q$5,$G17<=Q$5+4),"◆","") | R17: =IF(AND($G17>=R$5,$G17<=R$5+4),"◆","") | S17: =IF(AND($G17>=S$5,$G17<=S$5+4),"◆","")
A18: 1.5 | B18: Batch C (~10 attrs, third-party / ambiguous) – requirements | C18: BA / Business SME | D18: Task | E18: 5 | F18: 10 | G18: =WORKDAY($C$2,E18) -> 46307 | H18: =WORKDAY(G18,F18-1) -> 46318 | I18: 0.1 | J18: Not started | K18: 0
A19: 1.6 | B19: Batch C – source mapping, profiling (needs 3P sample) | C19: Data Analyst | D19: Task | E19: 12 | F19: 8 | G19: =WORKDAY($C$2,E19) -> 46316 | H19: =WORKDAY(G19,F19-1) -> 46325 | I19: 1.5, 2.2 | J19: Not started | K19: 0
A20: 1.7 | B20: Customer identity / key-stitching analysis across sources | C20: Data Architect | D20: Task | E20: 3 | F20: 9 | G20: =WORKDAY($C$2,E20) -> 46303 | H20: =WORKDAY(G20,F20-1) -> 46315 | I20: 1.1 | J20: Not started | K20: 0
A21: 1.8 | B21: Gap list: unsourced / partial attributes – resolution | C21: BA / Data Analyst | D21: Task | E21: 5 | F21: 15 | G21: =WORKDAY($C$2,E21) -> 46307 | H21: =WORKDAY(G21,F21-1) -> 46325 | I21: 1.2 | J21: Not started | K21: 0
A22: M1R | B22: Requirements baseline gate (Batch C conditional) | C22: PM / Business SME | D22: Milestone | E22: 14 | F22: 0 | G22: =WORKDAY($C$2,E22) -> 46318 | H22: =G22 -> 46318 | I22: M1A, M1B | J22: Not started | K22: 0 | L22: =IF(AND($G22>=L$5,$G22<=L$5+4),"◆","") | M22: =IF(AND($G22>=M$5,$G22<=M$5+4),"◆","") | N22: =IF(AND($G22>=N$5,$G22<=N$5+4),"◆","") -> ◆ | O22: =IF(AND($G22>=O$5,$G22<=O$5+4),"◆","") | P22: =IF(AND($G22>=P$5,$G22<=P$5+4),"◆","") | Q22: =IF(AND($G22>=Q$5,$G22<=Q$5+4),"◆","") | R22: =IF(AND($G22>=R$5,$G22<=R$5+4),"◆","") | S22: =IF(AND($G22>=S$5,$G22<=S$5+4),"◆","")
A23: M1C | B23: Batch C sign-off | C23: Business SME | D23: Milestone | E23: 19 | F23: 0 | G23: =WORKDAY($C$2,E23) -> 46325 | H23: =G23 -> 46325 | I23: 1.6 | J23: Not started | K23: 0 | L23: =IF(AND($G23>=L$5,$G23<=L$5+4),"◆","") | M23: =IF(AND($G23>=M$5,$G23<=M$5+4),"◆","") | N23: =IF(AND($G23>=N$5,$G23<=N$5+4),"◆","") | O23: =IF(AND($G23>=O$5,$G23<=O$5+4),"◆","") -> ◆ | P23: =IF(AND($G23>=P$5,$G23<=P$5+4),"◆","") | Q23: =IF(AND($G23>=Q$5,$G23<=Q$5+4),"◆","") | R23: =IF(AND($G23>=R$5,$G23<=R$5+4),"◆","") | S23: =IF(AND($G23>=S$5,$G23<=S$5+4),"◆","")
A24: 2 | B24: Third-Party Dependency Track (critical path) | D24: Phase | E24: =MIN(E25:E31) -> 0 | F24: =NETWORKDAYS(G24,H24) -> 30 | G24: =MIN(G25:G31) -> 46300 | H24: =MAX(H25:H31) -> 46339 | K24: =IF(SUMIF(D25:D31,"Task",F25:F31)=0,0,SUMPRODUCT((D25:D31="Task")*F25:F31*K25:K31)/SUMIF(D25:D31,"Task",F25:F31)) -> 0
A25: 2.1 | B25: Interface spec agreed (fields, format, frequency, keys, SLA) | C25: PM / Third party | D25: Task | E25: 0 | F25: 10 | G25: =WORKDAY($C$2,E25) -> 46300 | H25: =WORKDAY(G25,F25-1) -> 46311 | I25: 0.1 | J25: Not started | K25: 0
A26: M2S | B26: 3P interface spec signed | C26: Third party | D26: Milestone | E26: 9 | F26: 0 | G26: =WORKDAY($C$2,E26) -> 46311 | H26: =G26 -> 46311 | I26: 2.1 | J26: Not started | K26: 0 | L26: =IF(AND($G26>=L$5,$G26<=L$5+4),"◆","") | M26: =IF(AND($G26>=M$5,$G26<=M$5+4),"◆","") -> ◆ | N26: =IF(AND($G26>=N$5,$G26<=N$5+4),"◆","") | O26: =IF(AND($G26>=O$5,$G26<=O$5+4),"◆","") | P26: =IF(AND($G26>=P$5,$G26<=P$5+4),"◆","") | Q26: =IF(AND($G26>=Q$5,$G26<=Q$5+4),"◆","") | R26: =IF(AND($G26>=R$5,$G26<=R$5+4),"◆","") | S26: =IF(AND($G26>=S$5,$G26<=S$5+4),"◆","")
A27: 2.2 | B27: Sample data received & analysed | C27: Third party / Data Analyst | D27: Task | E27: 10 | F27: 5 | G27: =WORKDAY($C$2,E27) -> 46314 | H27: =WORKDAY(G27,F27-1) -> 46318 | I27: 2.1 | J27: Not started | K27: 0
A28: 2.3 | B28: Test feed delivered & validated | C28: Third party / Data Engineer | D28: Task | E28: 15 | F28: 5 | G28: =WORKDAY($C$2,E28) -> 46321 | H28: =WORKDAY(G28,F28-1) -> 46325 | I28: 2.2 | J28: Not started | K28: 0
A29: M2F | B29: Fallback decision: descope / stub 3P attrs if test feed not validated | C29: Steering | D29: Milestone | E29: 19 | F29: 0 | G29: =WORKDAY($C$2,E29) -> 46325 | H29: =G29 -> 46325 | I29: 2.3 | J29: Not started | K29: 0 | L29: =IF(AND($G29>=L$5,$G29<=L$5+4),"◆","") | M29: =IF(AND($G29>=M$5,$G29<=M$5+4),"◆","") | N29: =IF(AND($G29>=N$5,$G29<=N$5+4),"◆","") | O29: =IF(AND($G29>=O$5,$G29<=O$5+4),"◆","") -> ◆ | P29: =IF(AND($G29>=P$5,$G29<=P$5+4),"◆","") | Q29: =IF(AND($G29>=Q$5,$G29<=Q$5+4),"◆","") | R29: =IF(AND($G29>=R$5,$G29<=R$5+4),"◆","") | S29: =IF(AND($G29>=S$5,$G29<=S$5+4),"◆","")
A30: 2.4 | B30: Production feed setup & first delivery | C30: Third party / Data Engineer | D30: Task | E30: 25 | F30: 5 | G30: =WORKDAY($C$2,E30) -> 46335 | H30: =WORKDAY(G30,F30-1) -> 46339 | I30: 2.3 | J30: Not started | K30: 0
A31: M2P | B31: 3P production feed live | C31: Third party | D31: Milestone | E31: 29 | F31: 0 | G31: =WORKDAY($C$2,E31) -> 46339 | H31: =G31 -> 46339 | I31: 2.4 | J31: Not started | K31: 0 | L31: =IF(AND($G31>=L$5,$G31<=L$5+4),"◆","") | M31: =IF(AND($G31>=M$5,$G31<=M$5+4),"◆","") | N31: =IF(AND($G31>=N$5,$G31<=N$5+4),"◆","") | O31: =IF(AND($G31>=O$5,$G31<=O$5+4),"◆","") | P31: =IF(AND($G31>=P$5,$G31<=P$5+4),"◆","") | Q31: =IF(AND($G31>=Q$5,$G31<=Q$5+4),"◆","") -> ◆ | R31: =IF(AND($G31>=R$5,$G31<=R$5+4),"◆","") | S31: =IF(AND($G31>=S$5,$G31<=S$5+4),"◆","")
A32: 3 | B32: Design & Business Rules | D32: Phase | E32: =MIN(E33:E38) -> 5 | F32: =NETWORKDAYS(G32,H32) -> 20 | G32: =MIN(G33:G38) -> 46307 | H32: =MAX(H33:H38) -> 46332 | K32: =IF(SUMIF(D33:D38,"Task",F33:F38)=0,0,SUMPRODUCT((D33:D38="Task")*F33:F38*K33:K38)/SUMIF(D33:D38,"Task",F33:F38)) -> 0
A33: 3.1 | B33: Target model (bronze / silver / gold) & curated view design standards | C33: Data Architect | D33: Task | E33: 5 | F33: 7 | G33: =WORKDAY($C$2,E33) -> 46307 | H33: =WORKDAY(G33,F33-1) -> 46315 | I33: 1.1 | J33: Not started | K33: 0
A34: 3.2 | B34: Batch A – source-to-target mapping (STTM) & business rules | C34: Data Architect / BA | D34: Task | E34: 7 | F34: 8 | G34: =WORKDAY($C$2,E34) -> 46309 | H34: =WORKDAY(G34,F34-1) -> 46318 | I34: 1.2 | J34: Not started | K34: 0
A35: 3.3 | B35: Batch B – STTM & business rules | C35: Data Architect / BA | D35: Task | E35: 12 | F35: 8 | G35: =WORKDAY($C$2,E35) -> 46316 | H35: =WORKDAY(G35,F35-1) -> 46325 | I35: 1.4 | J35: Not started | K35: 0
A36: 3.4 | B36: Batch C – STTM & business rules | C36: Data Architect / BA | D36: Task | E36: 17 | F36: 8 | G36: =WORKDAY($C$2,E36) -> 46323 | H36: =WORKDAY(G36,F36-1) -> 46332 | I36: 1.6 | J36: Not started | K36: 0
A37: 3.5 | B37: Business rule review & approval (rolling) | C37: Business SME | D37: Task | E37: 12 | F37: 13 | G37: =WORKDAY($C$2,E37) -> 46316 | H37: =WORKDAY(G37,F37-1) -> 46332 | I37: 3.2 | J37: Not started | K37: 0
A38: M3 | B38: Design sign-off (all batches) | C38: Data Architect / Business SME | D38: Milestone | E38: 24 | F38: 0 | G38: =WORKDAY($C$2,E38) -> 46332 | H38: =G38 -> 46332 | I38: 3.4, 3.5 | J38: Not started | K38: 0 | L38: =IF(AND($G38>=L$5,$G38<=L$5+4),"◆","") | M38: =IF(AND($G38>=M$5,$G38<=M$5+4),"◆","") | N38: =IF(AND($G38>=N$5,$G38<=N$5+4),"◆","") | O38: =IF(AND($G38>=O$5,$G38<=O$5+4),"◆","") | P38: =IF(AND($G38>=P$5,$G38<=P$5+4),"◆","") -> ◆ | Q38: =IF(AND($G38>=Q$5,$G38<=Q$5+4),"◆","") | R38: =IF(AND($G38>=R$5,$G38<=R$5+4),"◆","") | S38: =IF(AND($G38>=S$5,$G38<=S$5+4),"◆","")
A39: 4 | B39: Integration & Build | D39: Phase | E39: =MIN(E40:E48) -> 5 | F39: =NETWORKDAYS(G39,H39) -> 25 | G39: =MIN(G40:G48) -> 46307 | H39: =MAX(H40:H48) -> 46339 | K39: =IF(SUMIF(D40:D48,"Task",F40:F48)=0,0,SUMPRODUCT((D40:D48="Task")*F40:F48*K40:K48)/SUMIF(D40:D48,"Task",F40:F48)) -> 0
A40: 4.1 | B40: Env setup: catalogs, schemas, permissions, CI/CD (Asset Bundles) | C40: Platform / DevOps | D40: Task | E40: 5 | F40: 10 | G40: =WORKDAY($C$2,E40) -> 46307 | H40: =WORKDAY(G40,F40-1) -> 46318 | I40: 0.2 | J40: Not started | K40: 0
A41: 4.2 | B41: Batch A – ingestion to bronze, conform to silver | C41: Data Engineer | D41: Task | E41: 12 | F41: 8 | G41: =WORKDAY($C$2,E41) -> 46316 | H41: =WORKDAY(G41,F41-1) -> 46325 | I41: 3.2, 4.1 | J41: Not started | K41: 0
...

Sheet Milestones
A1: Milestones & Gates
A3: ID | B3: Milestone / Gate | C3: Owner | D3: Date | E3: Week | F3: Status | G3: Days to go
A4: =Gantt!A10 -> M0 | B4: =Gantt!B10 -> Kickoff complete | C4: =Gantt!C10 -> PM | D4: =Gantt!G10 -> 46301 | E4: ="W"&(INT((D4-Gantt!$C$2)/7)+1) -> W1 | F4: =Gantt!J10 -> Not started | G4: =IF(F4="Done","-",NETWORKDAYS(TODAY(),D4)-1) -> 4
A5: =Gantt!A14 -> M1A | B5: =Gantt!B14 -> Batch A requirements + analysis sign-off | C5: =Gantt!C14 -> Business SME | D5: =Gantt!G14 -> 46311 | E5: ="W"&(INT((D5-Gantt!$C$2)/7)+1) -> W2 | F5: =Gantt!J14 -> Not started | G5: =IF(F5="Done","-",NETWORKDAYS(TODAY(),D5)-1) -> 12
A6: =Gantt!A17 -> M1B | B6: =Gantt!B17 -> Batch B requirements + analysis sign-off | C6: =Gantt!C17 -> Business SME | D6: =Gantt!G17 -> 46318 | E6: ="W"&(INT((D6-Gantt!$C$2)/7)+1) -> W3 | F6: =Gantt!J17 -> Not started | G6: =IF(F6="Done","-",NETWORKDAYS(TODAY(),D6)-1) -> 17
A7: =Gantt!A22 -> M1R | B7: =Gantt!B22 -> Requirements baseline gate (Batch C conditional) | C7: =Gantt!C22 -> PM / Business SME | D7: =Gantt!G22 -> 46318 | E7: ="W"&(INT((D7-Gantt!$C$2)/7)+1) -> W3 | F7: =Gantt!J22 -> Not started | G7: =IF(F7="Done","-",NETWORKDAYS(TODAY(),D7)-1) -> 17
A8: =Gantt!A23 -> M1C | B8: =Gantt!B23 -> Batch C sign-off | C8: =Gantt!C23 -> Business SME | D8: =Gantt!G23 -> 46325 | E8: ="W"&(INT((D8-Gantt!$C$2)/7)+1) -> W4 | F8: =Gantt!J23 -> Not started | G8: =IF(F8="Done","-",NETWORKDAYS(TODAY(),D8)-1) -> 22
A9: =Gantt!A26 -> M2S | B9: =Gantt!B26 -> 3P interface spec signed | C9: =Gantt!C26 -> Third party | D9: =Gantt!G26 -> 46311 | E9: ="W"&(INT((D9-Gantt!$C$2)/7)+1) -> W2 | F9: =Gantt!J26 -> Not started | G9: =IF(F9="Done","-",NETWORKDAYS(TODAY(),D9)-1) -> 12
A10: =Gantt!A29 -> M2F | B10: =Gantt!B29 -> Fallback decision: descope / stub 3P attrs if test feed not validated | C10: =Gantt!C29 -> Steering | D10: =Gantt!G29 -> 46325 | E10: ="W"&(INT((D10-Gantt!$C$2)/7)+1) -> W4 | F10: =Gantt!J29 -> Not started | G10: =IF(F10="Done","-",NETWORKDAYS(TODAY(),D10)-1) -> 22
A11: =Gantt!A31 -> M2P | B11: =Gantt!B31 -> 3P production feed live | C11: =Gantt!C31 -> Third party | D11: =Gantt!G31 -> 46339 | E11: ="W"&(INT((D11-Gantt!$C$2)/7)+1) -> W6 | F11: =Gantt!J31 -> Not started | G11: =IF(F11="Done","-",NETWORKDAYS(TODAY(),D11)-1) -> 32
A12: =Gantt!A38 -> M3 | B12: =Gantt!B38 -> Design sign-off (all batches) | C12: =Gantt!C38 -> Data Architect / Business SME | D12: =Gantt!G38 -> 46332 | E12: ="W"&(INT((D12-Gantt!$C$2)/7)+1) -> W5 | F12: =Gantt!J38 -> Not started | G12: =IF(F12="Done","-",NETWORKDAYS(TODAY(),D12)-1) -> 27
A13: =Gantt!A48 -> M4 | B13: =Gantt!B48 -> Build complete | C13: =Gantt!C48 -> Data Engineering Lead | D13: =Gantt!G48 -> 46339 | E13: ="W"&(INT((D13-Gantt!$C$2)/7)+1) -> W6 | F13: =Gantt!J48 -> Not started | G13: =IF(F13="Done","-",NETWORKDAYS(TODAY(),D13)-1) -> 32
A14: =Gantt!A56 -> M5 | B14: =Gantt!B56 -> SIT exit | C14: =Gantt!C56 -> QA Lead | D14: =Gantt!G56 -> 46344 | E14: ="W"&(INT((D14-Gantt!$C$2)/7)+1) -> W7 | F14: =Gantt!J56 -> Not started | G14: =IF(F14="Done","-",NETWORKDAYS(TODAY(),D14)-1) -> 35
A15: =Gantt!A62 -> M6 | B15: =Gantt!B62 -> UAT sign-off | C15: =Gantt!C62 -> Business SME | D15: =Gantt!G62 -> 46346 | E15: ="W"&(INT((D15-Gantt!$C$2)/7)+1) -> W7 | F15: =Gantt!J62 -> Not started | G15: =IF(F15="Done","-",NETWORKDAYS(TODAY(),D15)-1) -> 37
A16: =Gantt!A66 -> M7G | B16: =Gantt!B66 -> Go-live | C16: =Gantt!C66 -> PM | D16: =Gantt!G66 -> 46350 | E16: ="W"&(INT((D16-Gantt!$C$2)/7)+1) -> W8 | F16: =Gantt!J66 -> Not started | G16: =IF(F16="Done","-",NETWORKDAYS(TODAY(),D16)-1) -> 39
A17: =Gantt!A68 -> M7C | B17: =Gantt!B68 -> Project close | C17: =Gantt!C68 -> PM | D17: =Gantt!G68 -> 46353 | E17: ="W"&(INT((D17-Gantt!$C$2)/7)+1) -> W8 | F17: =Gantt!J68 -> Not started | G17: =IF(F17="Done","-",NETWORKDAYS(TODAY(),D17)-1) -> 42
B19: All cells link to the Gantt sheet (green) – update status there.

Sheet Attribute Tracker
A1: Attribute Tracker – 50 CJA attributes
A2: Fill one row per business attribute. Row 1 is a worked example (replace it). Yellow = drop-down status columns.
A4: Progress summary (count of attributes = Done)
A5: Batch | B5: Requirements | C5: Data analysis | D5: Design | E5: Build | F5: SIT | G5: UAT | H5: Total attrs
A6: A | B6: =COUNTIFS($D$13:$D$62,"A",K13:K62,"Done") -> 1 | C6: =COUNTIFS($D$13:$D$62,"A",L13:L62,"Done") -> 0 | D6: =COUNTIFS($D$13:$D$62,"A",M13:M62,"Done") -> 0 | E6: =COUNTIFS($D$13:$D$62,"A",N13:N62,"Done") -> 0 | F6: =COUNTIFS($D$13:$D$62,"A",O13:O62,"Done") -> 0 | G6: =COUNTIFS($D$13:$D$62,"A",P13:P62,"Done") -> 0 | H6: =COUNTIF($D$13:$D$62,"A") -> 20
A7: B | B7: =COUNTIFS($D$13:$D$62,"B",K13:K62,"Done") -> 0 | C7: =COUNTIFS($D$13:$D$62,"B",L13:L62,"Done") -> 0 | D7: =COUNTIFS($D$13:$D$62,"B",M13:M62,"Done") -> 0 | E7: =COUNTIFS($D$13:$D$62,"B",N13:N62,"Done") -> 0 | F7: =COUNTIFS($D$13:$D$62,"B",O13:O62,"Done") -> 0 | G7: =COUNTIFS($D$13:$D$62,"B",P13:P62,"Done") -> 0 | H7: =COUNTIF($D$13:$D$62,"B") -> 20
A8: C | B8: =COUNTIFS($D$13:$D$62,"C",K13:K62,"Done") -> 0 | C8: =COUNTIFS($D$13:$D$62,"C",L13:L62,"Done") -> 0 | D8: =COUNTIFS($D$13:$D$62,"C",M13:M62,"Done") -> 0 | E8: =COUNTIFS($D$13:$D$62,"C",N13:N62,"Done") -> 0 | F8: =COUNTIFS($D$13:$D$62,"C",O13:O62,"Done") -> 0 | G8: =COUNTIFS($D$13:$D$62,"C",P13:P62,"Done") -> 0 | H8: =COUNTIF($D$13:$D$62,"C") -> 10
A9: Total | B9: =COUNTIF(K13:K62,"Done") -> 1 | C9: =COUNTIF(L13:L62,"Done") -> 0 | D9: =COUNTIF(M13:M62,"Done") -> 0 | E9: =COUNTIF(N13:N62,"Done") -> 0 | F9: =COUNTIF(O13:O62,"Done") -> 0 | G9: =COUNTIF(P13:P62,"Done") -> 0 | H9: =COUNTA($B$13:$B$62) -> 50
A12: # | B12: Attribute name | C12: Business definition | D12: Batch | E12: Grain | F12: Source system(s) | G12: Source table.field | H12: 3P dependent? | I12: Business rule / derivation | J12: Target view | K12: Requirements | L12: Data analysis | M12: Design | N12: Build | O12: SIT | P12: UAT | Q12: Owner | R12: Comments
A13: 1 | B13: Last purchase date | C13: Date of the customer's most recent completed order | D13: A | E13: Customer | F13: Order Management (OMS) | G13: oms.orders.order_ts | H13: N | I13: MAX(order_ts) WHERE order_status = 'COMPLETED', per customer_id | J13: gold.v_cja_customer_profile | K13: Done | L13: In progress | M13: Not started | N13: Not started | O13: Not started | P13: Not started | Q13: BA – TBD | R13: Example row – replace
A14: 2 | B14: Attribute 02 | D14: A | H14: TBC | K14: Not started | L14: Not started | M14: Not started | N14: Not started | O14: Not started | P14: Not started
A15: 3 | B15: Attribute 03 | D15: A | H15: TBC | K15: Not started | L15: Not started | M15: Not started | N15: Not started | O15: Not started | P15: Not started
A16: 4 | B16: Attribute 04 | D16: A | H16: TBC | K16: Not started | L16: Not started | M16: Not started | N16: Not started | O16: Not started | P16: Not started
A17: 5 | B17: Attribute 05 | D17: A | H17: TBC | K17: Not started | L17: Not started | M17: Not started | N17: Not started | O17: Not started | P17: Not started
A18: 6 | B18: Attribute 06 | D18: A | H18: TBC | K18: Not started | L18: Not started | M18: Not started | N18: Not started | O18: Not started | P18: Not started
A19: 7 | B19: Attribute 07 | D19: A | H19: TBC | K19: Not started | L19: Not started | M19: Not started | N19: Not started | O19: Not started | P19: Not started
A20: 8 | B20: Attribute 08 | D20: A | H20: TBC | K20: Not started | L20: Not started | M20: Not started | N20: Not started | O20: Not started | P20: Not started
A21: 9 | B21: Attribute 09 | D21: A | H21: TBC | K21: Not started | L21: Not started | M21: Not started | N21: Not started | O21: Not started | P21: Not started
A22: 10 | B22: Attribute 10 | D22: A | H22: TBC | K22: Not started | L22: Not started | M22: Not started | N22: Not started | O22: Not started | P22: Not started
A23: 11 | B23: Attribute 11 | D23: A | H23: TBC | K23: Not started | L23: Not started | M23: Not started | N23: Not started | O23: Not started | P23: Not started
A24: 12 | B24: Attribute 12 | D24: A | H24: TBC | K24: Not started | L24: Not started | M24: Not started | N24: Not started | O24: Not started | P24: Not started
A25: 13 | B25: Attribute 13 | D25: A | H25: TBC | K25: Not started | L25: Not started | M25: Not started | N25: Not started | O25: Not started | P25: Not started
... A62: 50 | B62: Attribute 50 | D62: C | H62: Y | K62: Not started | L62: Not started | M62: Not started | N62: Not started | O62: Not started | P62: Not started

Sheet RAID Log
A1: RAID Log – Risks, Assumptions, Issues, Dependencies
A3: ID | B3: Type | C3: Description | D3: Impact | E3: Likelihood | F3: Owner | G3: Mitigation / action | H3: Due (week) | I3: Status
A4: R1 | B4: Risk | C4: Third-party feed (spec, sample, test feed) slips past W4, blocking Batch C build | D4: High | E4: High | F4: PM | G4: Contractual dates for spec/sample/test feed; weekly 3P checkpoint; fallback decision at end W4 (descope or stub Batch C attrs) | H4: W4 | I4: Open
A5: R2 | B5: Risk | C5: Source-system and Databricks/UC access requests take longer than 1 week | D5: High | E5: Medium | F5: Platform / DevOps | G5: Raise all access requests on day 1; named approver per source; escalate at W1 steering | H5: W1 | I5: Open
A6: R3 | B6: Risk | C6: Attribute definitions change after batch sign-off, forcing rework | D6: Medium | E6: Medium | F6: BA | G6: Batch sign-off baseline; change requests assessed against go-live date | H6: W3 | I6: Open
A7: R4 | B7: Risk | C7: Customer identity keys don't reconcile across sources, lowering match rate | D7: High | E7: Medium | F7: Data Architect | G7: Identity-stitching analysis in W1–W2; agree survivorship / match rules early | H7: W2 | I7: Open
A8: R5 | B8: Risk | C8: Business SMEs not available for UAT in W7 | D8: Medium | E8: Medium | F8: PM | G8: Book UAT testers and slots by W3 | H8: W3 | I8: Open
A9: A1 | B9: Assumption | C9: CJA consumes the Databricks curated views via an agreed connector/export pattern (to be confirmed in W1) | D9: High | E9: - | F9: Data Architect | G9: Confirm integration pattern & refresh SLA with CJA admin | H9: W1 | I9: Open
A10: A2 | B10: Assumption | C10: 50-attribute scope is fixed; additions go through change control | D10: Medium | E10: - | F10: PM | G10: Scope baseline at requirements gate | H10: W3 | I10: Open
A11: A3 | B11: Assumption | C11: Non-prod environments mirror prod closely enough for SIT/UAT | D11: Medium | E11: - | F11: Platform / DevOps | G11: Validate env parity during 4.1 | H11: W3 | I11: Open
A12: D1 | B12: Dependency | C12: Third party provides interface spec (W2), sample (W3), test feed (W4), prod feed (W6) | D12: High | E12: - | F12: Third party | G12: Tracked in Gantt section 2 | H12: W6 | I12: Open
A13: D2 | B13: Dependency | C13: Source-system owners provide access and SMEs for profiling | D13: High | E13: - | F13: PM | G13: Named contact per source system | H13: W1 | I13: Open
