Workbook

Sheet How to Use
A1: How to Use
A3: 1. Fill the cream cells (blue text) on Application Inventory, one row per application. Grey cells are formulas.
A4: 2. Usage Status: Active Users = 0 or not used for 6+ months → 'Not in use'.
A5: 3. Retirement drivers (0–4): low / no use · replacement named · out of support · low business value.
A6: Drivers are indicative only. Decision is chosen from the dropdown: Decommission · Retire · Retire + Archive · Retain · Pending.
A7: 4. Complexity: Data Archival Required = N → Easy · else High if many interfaces, large data or critical · else Medium.
A8: 5. Record what must remain after shutdown in Post-Retirement Requirement (archive, read-only, legal hold).
A9: 6. Decision is an input (cream cell). Record any exception or rationale in Comments / Questions.
A10: 7. TBD = information still to be confirmed with the owner.
A11: 8. Thresholds and the as-of date (01-May-2021) are on the Scoring Settings tab.
A12: 9. Status: Completed = switched off · In progress = executing now · Approved = funded and scheduled · Under Review = awaiting decision · On hold = paused · Rejected = retained.

Sheet Application Inventory
A1: Application Inventory
A2: Cream cells = inputs (blue text). Grey cells = formulas. TBD = to be confirmed. Rules and thresholds on the 'Scoring Settings' tab.
A3: Identity | F3: Ownership | I3: Usage & Value | O3: Infrastructure | V3: Data & Archival | AB3: Dependencies | AC3: Documentation | AF3: Cost & Contract | AK3: Decision | AN3: Plan
A4: App ID | B4: App Name | C4: Business Capability | D4: Line of Business | E4: Exposure (Internal / External / Partner) | F4: Business Owner | G4: IT Owner | H4: Infra Owner | I4: Active Users (last 90d) | J4: Last Used Date | K4: Usage Status | L4: Business Value (1-5) | M4: Criticality Tier (1-4) | N4: Replacement / Target App | O4: Hosting | P4: Server Hostname(s) | Q4: # Servers | R4: OS / Version | S4: Database / Version | T4: Data Centre / Cloud Region | U4: End-of-Support Date | V4: Data Type | W4: Data Volume (GB) | X4: PII / Regulated (Y/N) | Y4: Retention (yrs) | Z4: Data Archival Required (Y/N) | AA4: Post-Retirement Requirement | AB4: Interfaces (#) | AC4: User / Functional Docs | AD4: Technical Design Docs | AE4: Architecture Diagram | AF4: Annual Run Cost ($) | AG4: Contract End Date | AH4: Est. Decom Cost ($) | AI4: Annual Savings ($) | AJ4: Payback (months) | AK4: Retirement Drivers (0-4) | AL4: Decision | AM4: Complexity | AN4: Wave | AO4: Target Retirement Date | AP4: Status | AQ4: Comments / Questions
A5: 195761 | B5: Global Cash Position Reporter (Nordics) | C5: Treasury | D5: Finance | E5: Internal | I5: 145 | J5: 44297 | K5: =IF(B5="","",IF(AND(I5="",J5=""),"Unknown",IF(OR(AND(ISNUMBER(I5),I5=0),AND(ISNUMBER(J5),J5<=EDATE('Scoring Settings'!$B$4,-'Scoring Settings'!$B$5))),"Not in use",IF(AND(ISNUMBER(I5),I5<'Scoring Settings'!$B$6),"Low use","Active")))) -> Active | L5: 4 | M5: 2 | N5: SAP Concur | O5: PaaS | P5: Azure App Service (PaaS) | Q5: 0 | R5: N/A (PaaS) | S5: Cosmos DB | T5: Azure West Europe | U5: 44742 | V5: Structured | W5: 230 | X5: Y | Y5: 10 | Z5: Y | AA5: Reporting extract | AB5: 15 | AC5: Y | AD5: Y | AE5: N | AF5: 7000 | AG5: 48548 | AH5: 6500 | AI5: 5500 | AJ5: =IF(AND(ISNUMBER(AH5),ISNUMBER(AI5),N(AI5)>0),AH5/AI5*12,"") -> 14.181818 | AK5: =IF(B5="","",OR(K5="Not in use",K5="Low use")+AND(N5<>"",N5<>"TBD")+AND(ISNUMBER(U5),U5<=EDATE('Scoring Settings'!$B$4,'Scoring Settings'!$B$8))+AND(ISNUMBER(L5),L5<='Scoring Settings'!$B$7)) -> 1 | AL5: Migrate | AM5: =IF(B5="","",IF(Z5="N","Easy",IF(OR(AND(ISNUMBER(AB5),AB5>'Scoring Settings'!$B$11),AND(ISNUMBER(W5),W5>'Scoring Settings'!$B$12),AND(ISNUMBER(M5),M5<='Scoring Settings'!$B$13)),"High","Medium"))) -> High | AN5: Wave 1 | AO5: 44377 | AP5: In progress | AQ5: Funding approved; migration to SAP Concur scheduled
A6: 38051 | B6: Corporate Asset Register v2 | C6: Fixed Assets | D6: Finance | E6: Internal | I6: 0 | J6: 44003 | K6: =IF(B6="","",IF(AND(I6="",J6=""),"Unknown",IF(OR(AND(ISNUMBER(I6),I6=0),AND(ISNUMBER(J6),J6<=EDATE('Scoring Settings'!$B$4,-'Scoring Settings'!$B$5))),"Not in use",IF(AND(ISNUMBER(I6),I6<'Scoring Settings'!$B$6),"Low use","Active")))) -> Not in use | L6: 2 | M6: 4 | O6: IaaS | P6: carapp01, cardb01, carweb01, carfs01 | Q6: 4 | R6: Solaris 10 | S6: Oracle 11g | T6: Azure West Europe | U6: 44227 | V6: Structured | W6: 230 | X6: Y | Y6: 7 | Z6: Y | AA6: Archive + read-only | AB6: 3 | AC6: Partial | AD6: N | AE6: N | AF6: 55000 | AG6: 46599 | AH6: 42000 | AI6: 39500 | AJ6: =IF(AND(ISNUMBER(AH6),ISNUMBER(AI6),N(AI6)>0),AH6/AI6*12,"") -> 12.759494 | AK6: =IF(B6="","",OR(K6="Not in use",K6="Low use")+AND(N6<>"",N6<>"TBD")+AND(ISNUMBER(U6),U6<=EDATE('Scoring Settings'!$B$4,'Scoring Settings'!$B$8))+AND(ISNUMBER(L6),L6<='Scoring Settings'!$B$7)) -> 3 | AL6: Retire + Archive | AM6: =IF(B6="","",IF(Z6="N","Easy",IF(OR(AND(ISNUMBER(AB6),AB6>'Scoring Settings'!$B$11),AND(ISNUMBER(W6),W6>'Scoring Settings'!$B$12),AND(ISNUMBER(M6),M6<='Scoring Settings'!$B$13)),"High","Medium"))) -> Medium | AN6: Wave 1 | AO6: 44561 | AP6: Approved | AQ6: Read-only access needed for audit
A7: 126849 | B7: Benefits Enrolment Lite | C7: Benefits | D7: HR | E7: Internal | I7: 19 | J7: 44182 | K7: =IF(B7="","",IF(AND(I7="",J7=""),"Unknown",IF(OR(AND(ISNUMBER(I7),I7=0),AND(ISNUMBER(J7),J7<=EDATE('Scoring Settings'!$B$4,-'Scoring Settings'!$B$5))),"Not in use",IF(AND(ISNUMBER(I7),I7<'Scoring Settings'!$B$6),"Low use","Active")))) -> Low use | L7: 4 | M7: 1 | N7: Workday Recruiting | O7: On-prem DC | P7: fs-bel02 (file share) | Q7: 1 | R7: TBD | S7: MS Access 2010 | T7: TBD | U7: 45209 | V7: Both | W7: 540 | X7: Y | Y7: 7 | Z7: N | AA7: None | AB7: 18 | AC7: Partial | AD7: Partial | AE7: N | AF7: 49500 | AG7: 48426 | AH7: 82500 | AI7: 39500 | AJ7: =IF(AND(ISNUMBER(AH7),ISNUMBER(AI7),N(AI7)>0),AH7/AI7*12,"") -> 25.063291 | AK7: =IF(B7="","",OR(K7="Not in use",K7="Low use")+AND(N7<>"",N7<>"TBD")+AND(ISNUMBER(U7),U7<=EDATE('Scoring Settings'!$B$4,'Scoring Settings'!$B$8))+AND(ISNUMBER(L7),L7<='Scoring Settings'!$B$7)) -> 2 | AL7: Migrate | AM7: =IF(B7="","",IF(Z7="N","Easy",IF(OR(AND(ISNUMBER(AB7),AB7>'Scoring Settings'!$B$11),AND(ISNUMBER(W7),W7>'Scoring Settings'!$B$12),AND(ISNUMBER(M7),M7<='Scoring Settings'!$B$13)),"High","Medium"))) -> Easy | AN7: Wave 1 | AO7: 44500 | AP7: In progress | AQ7: Cut-over planned for Oct-21; parallel run scheduled Blocker: Archive platform capacity not confirmed Q: Can the enterprise archive take this volume this year?
A8: 87175 | B8: Warehouse Mgmt System (Nordics) | C8: Warehouse Mgmt | D8: Supply Chain | E8: Internal | I8: 122 | J8: 44270 | K8: =IF(B8="","",IF(AND(I8="",J8=""),"Unknown",IF(OR(AND(ISNUMBER(I8),I8=0),AND(ISNUMBER(J8),J8<=EDATE('Scoring Settings'!$B$4,-'Scoring Settings'!$B$5))),"Not in use",IF(AND(ISNUMBER(I8),I8<'Scoring Settings'!$B$6),"Low use","Active")))) -> Active | L8: 2 | M8: 4 | N8: Ariba | O8: IaaS | P8: wmsapp01, wmsdb01, wmsweb01, wmsfs01 | Q8: 4 | R8: Ubuntu 16.04 | S8: MySQL 5.7 | T8: AWS us-east-1 | U8: 44316 | V8: Both | W8: 22 | X8: Y | Y8: 10 | Z8: N | AA8: None | AB8: 3 | AC8: Y | AD8: N | AE8: Y | AF8: 38500 | AG8: 47542 | AH8: 40500 | AI8: 33500 | AJ8: =IF(AND(ISNUMBER(AH8),ISNUMBER(AI8),N(AI8)>0),AH8/AI8*12,"") -> 14.507463 | AK8: =IF(B8="","",OR(K8="Not in use",K8="Low use")+AND(N8<>"",N8<>"TBD")+AND(ISNUMBER(U8),U8<=EDATE('Scoring Settings'!$B$4,'Scoring Settings'!$B$8))+AND(ISNUMBER(L8),L8<='Scoring Settings'!$B$7)) -> 3 | AL8: Retire | AM8: =IF(B8="","",IF(Z8="N","Easy",IF(OR(AND(ISNUMBER(AB8),AB8>'Scoring Settings'!$B$11),AND(ISNUMBER(W8),W8>'Scoring Settings'!$B$12),AND(ISNUMBER(M8),M8<='Scoring Settings'!$B$13)),"High","Medium"))) -> Easy | AN8: Wave 1 | AO8: 44347 | AP8: On hold | AQ8: On hold - audit request needs system access until Q3
A9: 57496 | B9: Shared Licence Manager v3 | C9: Licence Mgmt | D9: IT | E9: Internal | I9: 449 | J9: 44309 | K9: =IF(B9="","",IF(AND(I9="",J9=""),"Unknown",IF(OR(AND(ISNUMBER(I9),I9=0),AND(ISNUMBER(J9),J9<=EDATE('Scoring Settings'!$B$4,-'Scoring Settings'!$B$5))),"Not in use",IF(AND(ISNUMBER(I9),I9<'Scoring Settings'!$B$6),"Low use","Active")))) -> Active | L9: 3 | M9: 4 | N9: Microsoft 365 | O9: On-prem DC | P9: slmapp01, slmdb01 | Q9: 2 | R9: SUSE Linux 11 | S9: Oracle 11g | T9: TBD | U9: 43555 | V9: Both | W9: 21 | X9: N | Y9: 2 | Z9: Y | AA9: Read-only access | AB9: 2 | AC9: N | AD9: Partial | AE9: Y | AF9: 24500 | AG9: 49460 | AH9: 25000 | AI9: 18500 | AJ9: =IF(AND(ISNUMBER(AH9),ISNUMBER(AI9),N(AI9)>0),AH9/AI9*12,"") -> 16.216216 | AK9: =IF(B9="","",OR(K9="Not in use",K9="Low use")+AND(N9<>"",N9<>"TBD")+AND(ISNUMBER(U9),U9<=EDATE('Scoring Settings'!$B$4,'Scoring Settings'!$B$8))+AND(ISNUMBER(L9),L9<='Scoring Settings'!$B$7)) -> 2 | AL9: Migrate | AM9: =IF(B9="","",IF(Z9="N","Easy",IF(OR(AND(ISNUMBER(AB9),AB9>'Scoring Settings'!$B$11),AND(ISNUMBER(W9),W9>'Scoring Settings'!$B$12),AND(ISNUMBER(M9),M9<='Scoring Settings'!$B$13)),"High","Medium"))) -> Medium | AN9: Wave 1 | AO9: 44377 | AP9: In progress | AQ9: Migration to Microsoft 365 70% complete; cut-over by end of May
A10: 151951 | B10: Intranet (SharePoint) (US) | C10: Collaboration | D10: IT | E10: Internal | I10: 0 | J10: 44305 | K10: =IF(B10="","",IF(AND(I10="",J10=""),"Unknown",IF(OR(AND(ISNUMBER(I10),I10=0),AND(ISNUMBER(J10),J10<=EDATE('Scoring Settings'!$B$4,-'Scoring Settings'!$B$5))),"Not in use",IF(AND(ISNUMBER(I10),I10<'Scoring Settings'!$B$6),"Low use","Active")))) -> Not in use | L10: 3 | M10: 4 | N10: Microsoft 365 | O10: SaaS | P10: N/A (SaaS) | Q10: 0 | R10: N/A | S10: N/A | T10: Vendor cloud (EU) | U10: 45777 | V10: Unstructured | W10: 220 | X10: N | Y10: 3 | Z10: Y | AA10: Legal hold | AB10: 0 | AC10: Y | AD10: Partial | AE10: Y | AF10: 37000 | AG10: 48548 | AH10: 59000 | AI10: 14500 | AJ10: =IF(AND(ISNUMBER(AH10),ISNUMBER(AI10),N(AI10)>0),AH10/AI10*12,"") -> 48.827586 | AK10: =IF(B10="","",OR(K10="Not in use",K10="Low use")+AND(N10<>"",N10<>"TBD")+AND(ISNUMBER(U10),U10<=EDATE('Scoring Settings'!$B$4,'Scoring Settings'!$B$8))+AND(ISNUMBER(L10),L10<='Scoring Settings'!$B$7)) -> 2 | AL10: Retire + Archive | AM10: =IF(B10="","",IF(Z10="N","Easy",IF(OR(AND(ISNUMBER(AB10),AB10>'Scoring Settings'!$B$11),AND(ISNUMBER(W10),W10>'Scoring Settings'!$B$12),AND(ISNUMBER(M10),M10<='Scoring Settings'!$B$13)),"High","Medium"))) -> Medium | AN10: Wave 1 | AO10: 44316 | AP10: Completed | AQ10: Data archived and validated; switched off Apr-21
A11: 105155 | B11: Shared Inventory Control (APAC) | C11: Inventory | D11: Supply Chain | E11: Partner | I11: 0 | J11: 44271 | K11: =IF(B11="","",IF(AND(I11="",J11=""),"Unknown",IF(OR(AND(ISNUMBER(I11),I11=0),AND(ISNUMBER(J11),J11<=EDATE('Scoring Settings'!$B$4,-'Scoring Settings'!$B$5))),"Not in use",IF(AND(ISNUMBER(I11),I11<'Scoring Settings'!$B$6),"Low use","Active")))) -> Not in use | L11: 1 | M11: 4 | O11: PaaS | P11: Azure App Service (PaaS) | Q11: 0 | R11: N/A (PaaS) | S11: Azure SQL | T11: Azure West Europe | V11: Structured | W11: 100 | X11: N | Y11: 1 | Z11: N | AA11: None | AB11: 2 | AC11: N | AD11: Y | AE11: N | AF11: 170000 | AG11: 46234 | AH11: 20000 | AI11: 97000 | AJ11: =IF(AND(ISNUMBER(AH11),ISNUMBER(AI11),N(AI11)>0),AH11/AI11*12,"") -> 2.4742268 | AK11: =IF(B11="","",OR(K11="Not in use",K11="Low use")+AND(N11<>"",N11<>"TBD")+AND(ISNUMBER(U11),U11<=EDATE('Scoring Settings'!$B$4,'Scoring Settings'!$B$8))+AND(ISNUMBER(L11),L11<='Scoring Settings'!$B$7)) -> 2 | AL11: Retire | AM11: =IF(B11="","",IF(Z11="N","Easy",IF(OR(AND(ISNUMBER(AB11),AB11>'Scoring Settings'!$B$11),AND(ISNUMBER(W11),W11>'Scoring Settings'!$B$12),AND(ISNUMBER(M11),M11<='Scoring Settings'!$B$13)),"High","Medium"))) -> Easy | AN11: Wave 1 | AO11: 44286 | AP11: Completed | AQ11: Switched off Mar-21; licence terminated
A12: 32005 | B12: Global Shipment Tracker | C12: Logistics | D12: Supply Chain | E12: Internal | I12: 0 | J12: 44245 | K12: =IF(B12="","",IF(AND(I12="",J12=""),"Unknown",IF(OR(AND(ISNUMBER(I12),I12=0),AND(ISNUMBER(J12),J12<=EDATE('Scoring Settings'!$B$4,-'Scoring Settings'!$B$5))),"Not in use",IF(AND(ISNUMBER(I12),I12<'Scoring Settings'!$B$6),"Low use","Active")))) -> Not in use | L12: 3 | M12: 3 | N12: Oracle SCM Cloud | O12: SaaS | P12: N/A (SaaS) | Q12: 0 | R12: N/A | S12: N/A | T12: Vendor cloud (EU) | V12: Structured | W12: 170 | X12: N | Y12: 2 | Z12: N | AA12: None | AB12: 8 | AC12: Partial | AD12: Partial | AE12: N | AF12: 234500 | AG12: 46203 | AH12: 54000 | AI12: 246500 | AJ12: =IF(AND(ISNUMBER(AH12),ISNUMBER(AI12),N(AI12)>0),AH12/AI12*12,"") -> 2.6288032 | AK12: =IF(B12="","",OR(K12="Not in use",K12="Low use")+AND(N12<>"",N12<>"TBD")+AND(ISNUMBER(U12),U12<=EDATE('Scoring Settings'!$B$4,'Scoring Settings'!$B$8))+AND(ISNUMBER(L12),L12<='Scoring Settings'!$B$7)) -> 2 | AL12: Migrate | AM12: =IF(B12="","",IF(Z12="N","Easy",IF(OR(AND(ISNUMBER(AB12),AB12>'Scoring Settings'!$B$11),AND(ISNUMBER(W12),W12>'Scoring Settings'!$B$12),AND(ISNUMBER(M12),M12<='Scoring Settings'!$B$13)),"High","Medium"))) -> Easy | AN12: Wave 1 | AO12: 44255 | AP12: Completed | AQ12: Migrated to Oracle SCM Cloud; legacy switched off Feb-21
A13: 187888 | B13: Customer Contact Manager (DE) | C13: CRM | D13: Sales | E13: Partner | I13: 0 | J13: 44310 | K13: =IF(B13="","",IF(AND(I13="",J13=""),"Unknown",IF(OR(AND(ISNUMBER(I13),I13=0),AND(ISNUMBER(J13),J13<=EDATE('Scoring Settings'!$B$4,-'Scoring Settings'!$B$5))),"Not in use",IF(AND(ISNUMBER(I13),I13<'Scoring Settings'!$B$6),"Low use","Active")))) -> Not in use | L13: 3 | M13: 3 | N13: Salesforce | O13: On-prem DC | P13: ccmapp01 | Q13: 1 | R13: Solaris 10 | S13: Oracle 11g | T13: EU DC-2 | U13: 44227 | V13: Structured | W13: 230 | X13: Y | Y13: 10 | Z13: N | AA13: None | AB13: 8 | AC13: N | AD13: Partial | AE13: Partial | AF13: 123000 | AG13: 45777 | AH13: 12000 | AI13: 161000 | AJ13: =IF(AND(ISNUMBER(AH13),ISNUMBER(AI13),N(AI13)>0),AH13/AI13*12,"") -> 0.89440994 | AK13: =IF(B13="","",OR(K13="Not in use",K13="Low use")+AND(N13<>"",N13<>"TBD")+AND(ISNUMBER(U13),U13<=EDATE('Scoring Settings'!$B$4,'Scoring Settings'!$B$8))+AND(ISNUMBER(L13),L13<='Scoring Settings'!$B$7)) -> 3 | AL13: Retire | AM13: =IF(B13="","",IF(Z13="N","Easy",IF(OR(AND(ISNUMBER(AB13),AB13>'Scoring Settings'!$B$11),AND(ISNUMBER(W13),W13>'Scoring Settings'!$B$12),AND(ISNUMBER(M13),M13<='Scoring Settings'!$B$13)),"High","Medium"))) -> Easy | AN13: Wave 1 | AO13: 44316 | AP13: Completed | AQ13: Switched off Apr-21; licence terminated
A14: 80130 | B14: Price List Manager | C14: Pricing | D14: Sales | E14: Internal | I14: 0 | J14: 44115 | K14: =IF(B14="","",IF(AND(I14="",J14=""),"Unknown",IF(OR(AND(ISNUMBER(I14),I14=0),AND(ISNUMBER(J14),J14<=EDATE('Scoring Settings'!$B$4,-'Scoring Settings'!$B$5))),"Not in use",IF(AND(ISNUMBER(I14),I14<'Scoring Settings'!$B$6),"Low use","Active")))) -> Not in use | L14: 1 | M14: 3 | N14: TBD | O14: On-prem DC | P14: plmapp01, plmdb01, plmweb01, plmfs01 | Q14: 4 | R14: Windows Server 2016 | S14: SQL Server 2017 | T14: TBD | U14: 46399 | V14: Structured | W14: 990 | X14: Y | Y14: 7 | Z14: Y | AA14: Reporting extract | AB14: 4 | AC14: Partial | AD14: Partial | AE14: N | AF14: 65000 | AG14: 46965 | AH14: 94500 | AI14: 53500 | AJ14: =IF(AND(ISNUMBER(AH14),ISNUMBER(AI14),N(AI14)>0),AH14/AI14*12,"") -> 21.196262 | AK14: =IF(B14="","",OR(K14="Not in use",K14="Low use")+AND(N14<>"",N14<>"TBD")+AND(ISNUMBER(U14),U14<=EDATE('Scoring Settings'!$B$4,'Scoring Settings'!$B$8))+AND(ISNUMBER(L14),L14<='Scoring Settings'!$B$7)) -> 2 | AL14: Retire + Archive | AM14: =IF(B14="","",IF(Z14="N","Easy",IF(OR(AND(ISNUMBER(AB14),AB14>'Scoring Settings'!$B$11),AND(ISNUMBER(W14),W14>'Scoring Settings'!$B$12),AND(ISNUMBER(M14),M14<='Scoring Settings'!$B$13)),"High","Medium"))) -> Medium | AN14: Wave 1 | AO14: 44408 | AP14: In progress | AQ14: Archive format agreed; load scheduled before switch-off
A15: 37239 | B15: Corporate Ticket Desk | C15: Service Desk | D15: IT | E15: Partner | I15: 1202 | J15: 44304 | K15: =IF(B15="","",IF(AND(I15="",J15=""),"Unknown",IF(OR(AND(ISNUMBER(I15),I15=0),AND(ISNUMBER(J15),J15<=EDATE('Scoring Settings'!$B$4,-'Scoring Settings'!$B$5))),"Not in use",IF(AND(ISNUMBER(I15),I15<'Scoring Settings'!$B$6),"Low use","Active")))) -> Active | L15: 1 | M15: 4 | N15: Splunk | O15: On-prem DC | P15: ctdapp01, ctddb01, ctdweb01 | Q15: 3 | R15: SUSE Linux 11 | S15: TBD | T15: EU DC-1 | U15: TBD | V15: Structured | W15: 100 | X15: N | Y15: 1 | Z15: N | AA15: None | AB15: 0 | AC15: N | AD15: Partial | AE15: Partial | AF15: 55000 | AG15: 47330 | AH15: 47500 | AI15: 51000 | AJ15: =IF(AND(ISNUMBER(AH15),ISNUMBER(AI15),N(AI15)>0),AH15/AI15*12,"") -> 11.176471 | AK15: =IF(B15="","",OR(K15="Not in use",K15="Low use")+AND(N15<>"",N15<>"TBD")+AND(ISNUMBER(U15),U15<=EDATE('Scoring Settings'!$B$4,'Scoring Settings'!$B$8))+AND(ISNUMBER(L15),L15<='Scoring Settings'!$B$7)) -> 2 | AL15: Retire | AM15: =IF(B15="","",IF(Z15="N","Easy",IF(OR(AND(ISNUMBER(AB15),AB15>'Scoring Settings'!$B$11),AND(ISNUMBER(W15),W15>'Scoring Settings'!$B$12),AND(ISNUMBER(M15),M15<='Scoring Settings'!$B$13)),"High","Medium"))) -> Easy | AN15: Wave 1 | AO15: 44439 | AP15: In progress | AQ15: Functionality covered by existing tools
A16: 43206 | B16: Custom Batch Scheduler (APAC) | C16: Batch Scheduling | D16: IT | E16: Internal | I16: 22 | J16: 44204 | K16: =IF(B16="","",IF(AND(I16="",J16=""),"Unknown",IF(OR(AND(ISNUMBER(I16),I16=0),AND(ISNUMBER(J16),J16<=EDATE('Scoring Settings'!$B$4,-'Scoring Settings'!$B$5))),"Not in use",IF(AND(ISNUMBER(I16),I16<'Scoring Settings'!$B$6),"Low use","Active")))) -> Low use | L16: 4 | M16: 2 | N16: ServiceNow | O16: On-prem DC | P16: cbs-app01–05, cbs-db01 | Q16: 6 | R16: AIX 7.1 | S16: DB2 10.5 | T16: Plant DC | U16: 45046 | V16: Structured | W16: 67 | X16: Y | Y16: 7 | Z16: N | AA16: None | AB16: 26 | AC16: N | AD16: Partial | AE16: Partial | AF16: 95000 | AG16: 47026 | AH16: 87500 | AI16: 71500 | AJ16: =IF(AND(ISNUMBER(AH16),ISNUMBER(AI16),N(AI16)>0),AH16/AI16*12,"") -> 14.685315 | AK16: =IF(B16="","",OR(K16="Not in use",K16="Low use")+AND(N16<>"",N16<>"TBD")+AND(ISNUMBER(U16),U16<=EDATE('Scoring Settings'!$B$4,'Scoring Settings'!$B$8))+AND(ISNUMBER(L16),L16<='Scoring Settings'!$B$7)) -> 2 | AL16: Migrate | AM16: =IF(B16="","",IF(Z16="N","Easy",IF(OR(AND(ISNUMBER(AB16),AB16>'Scoring Settings'!$B$11),AND(ISNUMBER(W16),W16>'Scoring Settings'!$B$12),AND(ISNUMBER(M16),M16<='Scoring Settings'!$B$13)),"High","Medium"))) -> Easy | AN16: Wave 1 | AO16: 44408 | AP16: In progress | AQ16: Cut-over planned for Jul-21; parallel run scheduled
A17: 93717 | B17: Regional Facilities Request Portal (Nordics) | C17: Facilities | D17: Operations | E17: Internal | I17: 5 | J17: 43952 | K17: =IF(B17="","",IF(AND(I17="",J17=""),"Unknown",IF(OR(AND(ISNUMBER(I17),I17=0),AND(ISNUMBER(J17),J17<=EDATE('Scoring Settings'!$B$4,-'Scoring Settings'!$B$5))),"Not in use",IF(AND(ISNUMBER(I17),I17<'Scoring Settings'!$B$6),"Low use","Active")))) -> Not in use | L17: 2 | M17: 3 | N17: IBM Maximo | O17: On-prem DC | P17: rfrapp01, rfrdb01, rfrweb01, rfrfs01 | Q17: 4 | R17: RHEL 6 | S17: Oracle 11g | T17: Plant DC | U17: 44165 | V17: Both | W17: 260 | X17: N | Y17: 3 | Z17: Y | AA17: Archive + read-only | AB17: 4 | AC17: Partial | AD17: Partial | AE17: N | AF17: 50000 | AG17: 45747 | AH17: 25000 | AI17: 28500 | AJ17: =IF(AND(ISNUMBER(AH17),ISNUMBER(AI17),N(AI17)>0),AH17/AI17*12,"") -> 10.526316 | AK17: =IF(B17="","",OR(K17="Not in use",K17="Low use")+AND(N17<>"",N17<>"TBD")+AND(ISNUMBER(U17),U17<=EDATE('Scoring Settings'!$B$4,'Scoring Settings'!$B$8))+AND(ISNUMBER(L17),L17<='Scoring Settings'!$B$7)) -> 4 | AL17: Retire + Archive | AM17: =IF(B17="","",IF(Z17="N","Easy",IF(OR(AND(ISNUMBER(AB17),AB17>'Scoring Settings'!$B$11),AND(ISNUMBER(W17),W17>'Scoring Settings'!$B$12),AND(ISNUMBER(M17),M17<='Scoring Settings'!$B$13)),"High","Medium"))) -> Medium | AN17: Wave 1 | AO17: 44530 | AP17: In progress | AQ17: Read-only access needed for audit
A18: 45114 | B18: Regional Timesheet Portal 2012 | C18: Time & Attendance | D18: HR | E18: Internal | I18: 11 | J18: 44298 | K18: =IF(B18="","",IF(AND(I18="",J18=""),"Unknown",IF(OR(AND(ISNUMBER(I18),I18=0),AND(ISNUMBER(J18),J18<=EDATE('Scoring Settings'!$B$4,-'Scoring Settings'!$B$5))),"Not in use",IF(AND(ISNUMBER(I18),I18<'Scoring Settings'!$B$6),"Low use","Active")))) -> Low use | L18: 2 | M18: 3 | O18: PaaS | P18: Azure App Service (PaaS) | Q18: 0 | R18: N/A (PaaS) | S18: Azure SQL | T18: Azure West Europe | U18: 44742 | V18: Both | W18: 140 | X18: Y | Y18: 10 | Z18: N | AA18: None | AB18: 3 | AC18: Partial | AD18: N | AE18: Y | AF18: 8500 | AG18: 46783 | AH18: 9000 | AI18: 77500 | AJ18: =IF(AND(ISNUMBER(AH18),ISNUMBER(AI18),N(AI18)>0),AH18/AI18*12,"") -> 1.3935484 | AK18: =IF(B18="","",OR(K18="Not in use",K18="Low use")+AND(N18<>"",N18<>"TBD")+AND(ISNUMBER(U18),U18<=EDATE('Scoring Settings'!$B$4,'Scoring Settings'!$B$8))+AND(ISNUMBER(L18),L18<='Scoring Settings'!$B$7)) -> 2 | AL18: Retire | AM18: =IF(B18="","",IF(Z18="N","Easy",IF(OR(AND(ISNUMBER(AB18),AB18>'Scoring Settings'!$B$11),AND(ISNUMBER(W18),W18>'Scoring Settings'!$B$12),AND(ISNUMBER(M18),M18<='Scoring Settings'!$B$13)),"High","Medium"))) -> Easy | AN18: Wave 1 | AO18: 44347 | AP18: On hold | AQ18: On hold - audit request needs system access until Q3
A19: 99137 | B19: Global Newsletter Mailer (DE) | C19: Email | D19: Marketing | E19: Internal | I19: 0 | J19: 44279 | K19: =IF(B19="","",IF(AND(I19="",J19=""),"Unknown",IF(OR(AND(ISNUMBER(I19),I19=0),AND(ISNUMBER(J19),J19<=EDATE('Scoring Settings'!$B$4,-'Scoring Settings'!$B$5))),"Not in use",IF(AND(ISNUMBER(I19),I19<'Scoring Settings'!$B$6),"Low use","Active")))) -> Not in use | L19: 1 | M19: 3 | N19: TBD | O19: On-prem DC | P19: gnmapp01, gnmdb01, gnmweb01, gnmfs01 | Q19: 4 | R19: Windows Server 2012 R2 | S19: SQL Server 2014 | T19: US DC-1 | U19: 45482 | V19: Both | W19: 55 | X19: Y | Y19: 10 | Z19: N | AA19: None | AB19: 2 | AC19: Partial | AD19: N | AE19: Partial | AF19: 55000 | AG19: 47938 | AH19: 53000 | AI19: 95500 | AJ19: =IF(AND(ISNUMBER(AH19),ISNUMBER(AI19),N(AI19)>0),AH19/AI19*12,"") -> 6.6596859 | AK19: =IF(B19="","",OR(K19="Not in use",K19="Low use")+AND(N19<>"",N19<>"TBD")+AND(ISNUMBER(U19),U19<=EDATE('Scoring Settings'!$B$4,'Scoring Settings'!$B$8))+AND(ISNUMBER(L19),L19<='Scoring Settings'!$B$7)) -> 2 | AL19: Retire | AM19: =IF(B19="","",IF(Z19="N","Easy",IF(OR(AND(ISNUMBER(AB19),AB19>'Scoring Settings'!$B$11),AND(ISNUMBER(W19),W19>'Scoring Settings'!$B$12),AND(ISNUMBER(M19),M19<='Scoring Settings'!$B$13)),"High","Medium"))) -> Easy | AN19: Wave 1 | AO19: 44286 | AP19: Completed | AQ19: Switched off Mar-21; licence terminated
A20: 85637 | B20: Core ERP (SAP ECC) | C20: Enterprise Resource Planning | D20: Finance | E20: Partner | I20: 2400 | J20: 44316 | K20: =IF(B20="","",IF(AND(I20="",J20=""),"Unknown",IF(OR(AND(ISNUMBER(I20),I20=0),AND(ISNUMBER(J20),J20<=EDATE('Scoring Settings'!$B$4,-'Scoring Settings'!$B$5))),"Not in use",IF(AND(ISNUMBER(I20),I20<'Scoring Settings'!$B$6),"Low use","Active")))) -> Active | L20: 5 | M20: 1 | N20: SAP S/4HANA | O20: On-prem DC | P20: ecc-app01–05, ecc-db01 | Q20: 6 | R20: SUSE Linux 11 | S20: Oracle 11g | T20: EU DC-1 | U20: 46022 | V20: Structured | W20: 4500 | X20: Y | Y20: 10 | Z20: N | AA20: None | AB20: 85 | AC20: Y | AD20: Y | AE20: Partial | AF20: 650000 | AG20: 46387 | AH20: 32200000 | AI20: 520000 | AJ20: =IF(AND(ISNUMBER(AH20),ISNUMBER(AI20),N(AI20)>0),AH20/AI20*12,"") -> 743.07692 | AK20: =IF(B20="","",OR(K20="Not in use",K20="Low use")+AND(N20<>"",N20<>"TBD")+AND(ISNUMBER(U20),U20<=EDATE('Scoring Settings'!$B$4,'Scoring Settings'!$B$8))+AND(ISNUMBER(L20),L20<='Scoring Settings'!$B$7)) -> 1 | AL20: Retire | AM20: =IF(B20="","",IF(Z20="N","Easy",IF(OR(AND(ISNUMBER(AB20),AB20>'Scoring Settings'!$B$11),AND(ISNUMBER(W20),W20>'Scoring Settings'!$B$12),AND(ISNUMBER(M20),M20<='Scoring Settings'!$B$13)),"High","Medium"))) -> Easy | AN20: Wave 1 | AO20: 44500 | AP20: In progress | AQ20: Retire after S/4HANA cut-over; finance history retained in S/4HANA - no separate archive
A21: 138296 | B21: Old CMDB Lite | C21: Config Mgmt | D21: IT | E21: External | I21: 8 | J21: 44168 | K21: =IF(B21="","",IF(AND(I21="",J21=""),"Unknown",IF(OR(AND(ISNUMBER(I21),I21=0),AND(ISNUMBER(J21),J21<=EDATE('Scoring Settings'!$B$4,-'Scoring Settings'!$B$5))),"Not in use",IF(AND(ISNUMBER(I21),I21<'Scoring Settings'!$B$6),"Low use","Active")))) -> Low use | L21: 5 | M21: 1 | N21: ServiceNow (planned) | O21: On-prem DC | P21: ocl-app01–04, ocl-db01 | Q21: 5 | R21: Windows Server 2008 R2 | S21: SQL Server 2008 R2 | T21: TBD | U21: 43844 | V21: Structured | W21: 19 | X21: N | Y21: 7 | Z21: Y | AA21: Archive + read-only | AB21: 35 | AC21: Partial | AD21: N | AE21: Partial | AF21: 195000 | AG21: 47999 | AH21: 245000 | AI21: 267500 | AJ21: =IF(AND(ISNUMBER(AH21),ISNUMBER(AI21),N(AI21)>0),AH21/AI21*12,"") -> 10.990654 | AK21: =IF(B21="","",OR(K21="Not in use",K21="Low use")+AND(N21<>"",N21<>"TBD")+AND(ISNUMBER(U21),U21<=EDATE('Scoring Settings'!$B$4,'Scoring Settings'!$B$8))+AND(ISNUMBER(L21),L21<='Scoring Settings'!$B$7)) -> 3 | AL21: Migrate | AM21: =IF(B21="","",IF(Z21="N","Easy",IF(OR(AND(ISNUMBER(AB21),AB21>'Scoring Settings'!$B$11),AND(ISNUMBER(W21),W21>'Scoring Settings'!$B$12),AND(ISNUMBER(M21),M21<='Scoring Settings'!$B$13)),"High","Medium"))) -> High | AN21: Wave 1 | AO21: 44469 | AP21: In progress | AQ21: 3 feeds to re-point to ServiceNow
A22: 166902 | B22: Supplier Portal | C22: Supplier Mgmt | D22: Supply Chain | E22: Internal | I22: 0 | J22: 43732 | K22: =IF(B22="","",IF(AND(I22="",J22=""),"Unknown",IF(OR(AND(ISNUMBER(I22),I22=0),AND(ISNUMBER(J22),J22<=EDATE('Scoring Settings'!$B$4,-'Scoring Settings'!$B$5))),"Not in use",IF(AND(ISNUMBER(I22),I22<'Scoring Settings'!$B$6),"Low use","Active")))) -> Not in use | L22: 2 | M22: 3 | O22: On-prem DC | P22: spxapp01, spxdb01, spxweb01, spxfs01 | Q22: 4 | R22: Windows Server 2008 R2 | S22: SQL Server 2008 R2 | T22: EU DC-1 | U22: 43844 | V22: Both | W22: 110 | X22: N | Y22: 7 | Z22: N | AA22: None | AB22: 2 | AC22: N | AD22: Partial | AE22: N | AF22: 80000 | AG22: 45777 | AH22: 39000 | AI22: 77000 | AJ22: =IF(AND(ISNUMBER(AH22),ISNUMBER(AI22),N(AI22)>0),AH22/AI22*12,"") -> 6.0779221 | AK22: =IF(B22="","",OR(K22="Not in use",K22="Low use")+AND(N22<>"",N22<>"TBD")+AND(ISNUMBER(U22),U22<=EDATE('Scoring Settings'!$B$4,'Scoring Settings'!$B$8))+AND(ISNUMBER(L22),L22<='Scoring Settings'!$B$7)) -> 3 | AL22: Retire | AM22: =IF(B22="","",IF(Z22="N","Easy",IF(OR(AND(ISNUMBER(AB22),AB22>'Scoring Settings'!$B$11),AND(ISNUMBER(W22),W22>'Scoring Settings'!$B$12),AND(ISNUMBER(M22),M22<='Scoring Settings'!$B$13)),"High","Medium"))) -> Easy | AN22: Wave 1 | AO22: 44469 | AP22: In progress | AQ22: Functionality covered by existing tools
A23: 18048 | B23: Corporate Inventory Control (UK) | C23: Inventory | D23: Supply Chain | E23: Internal | I23: 22 | J23: 44230 | K23: =IF(B23="","",IF(AND(I23="",J23=""),"Unknown",IF(OR(AND(ISNUMBER(I23),I23=0),AND(ISNUMBER(J23),J23<=EDATE('Scoring Settings'!$B$4,-'Scoring Settings'!$B$5))),"Not in use",IF(AND(ISNUMBER(I23),I23<'Scoring Settings'!$B$6),"Low use","Active")))) -> Low use | L23: 3 | M23: 3 | N23: TBD | O23: SaaS | P23: N/A (SaaS) | Q23: 0 | R23: N/A | S23: N/A | T23: Vendor cloud (EU) | V23: Unstructured | W23: 120 | X23: N | Y23: 3 | Z23: Y | AA23: Data archive | AB23: 8 | AC23: Partial | AD23: Partial | AE23: Partial | AF23: 90000 | AG23: 48487 | AH23: 52500 | AI23: 32500 | AJ23: =IF(AND(ISNUMBER(AH23),ISNUMBER(AI23),N(AI23)>0),AH23/AI23*12,"") -> 19.384615 | AK23: =IF(B23="","",OR(K23="Not in use",K23="Low use")+AND(N23<>"",N23<>"TBD")+AND(ISNUMBER(U23),U23<=EDATE('Scoring Settings'!$B$4,'Scoring Settings'!$B$8))+AND(ISNUMBER(L23),L23<='Scoring Settings'!$B$7)) -> 1 | AL23: Retire + Archive | AM23: =IF(B23="","",IF(Z23="N","Easy",IF(OR(AND(ISNUMBER(AB23),AB23>'Scoring Settings'!$B$11),AND(ISNUMBER(W23),W23>'Scoring Settings'!$B$12),AND(ISNUMBER(M23),M23<='Scoring Settings'!$B$13)),"High","Medium"))) -> High | AN23: Wave 1 | AO23: 44408 | AP23: In progress | AQ23: Retention 3 yrs - archive slot booked
A24: 161444 | B24: Corporate Access Request Tool (UK) | C24: Identity | D24: IT | E24: Internal | I24: 44 | J24: 44274 | K24: =IF(B24="","",IF(AND(I24="",J24=""),"Unknown",IF(OR(AND(ISNUMBER(I24),I24=0),AND(ISNUMBER(J24),J24<=EDATE('Scoring Settings'!$B$4,-'Scoring Settings'!$B$5))),"Not in use",IF(AND(ISNUMBER(I24),I24<'Scoring Settings'!$B$6),"Low use","Active")))) -> Active | L24: 3 | M24: 2 | N24: Azure Monitor | O24: On-prem DC | P24: car-app01–05, car-db01 | Q24: 6 | R24: SUSE Linux 11 | S24: Oracle 11g | T24: Plant DC | U24: 43555 | V24: Structured | W24: 30 | X24: N | Y24: 7 | Z24: Y | AA24: Read-only access | AB24: 12 | AC24: Partial | AD24: Partial | AE24: N | AF24: 125000 | AG24: 46265 | AH24: 256000 | AI24: 84000 | AJ24: =IF(AND(ISNUMBER(AH24),ISNUMBER(AI24),N(AI24)>0),AH24/AI24*12,"") -> 36.571429 | AK24: =IF(B24="","",OR(K24="Not in use",K24="Low use")+AND(N24<>"",N24<>"TBD")+AND(ISNUMBER(U24),U24<=EDATE('Scoring Settings'!$B$4,'Scoring Settings'!$B$8))+AND(ISNUMBER(L24),L24<='Scoring Settings'!$B$7)) -> 2 | AL24: Retire + Archive | AM24: =IF(B24="","",IF(Z24="N","Easy",IF(OR(AND(ISNUMBER(AB24),AB24>'Scoring Settings'!$B$11),AND(ISNUMBER(W24),W24>'Scoring Settings'!$B$12),AND(ISNUMBER(M24),M24<='Scoring Settings'!$B$13)),"High","Medium"))) -> High | AN24: Wave 1 | AO24: 44408 | AP24: In progress | AQ24: Read-only access needed for audit
A25: 186996 | B25: Departmental Quality Incident Log v2 | C25: Quality | D25: Operations | E25: Internal | I25: 11 | J25: 44170 | K25: =IF(B25="","",IF(AND(I25="",J25=""),"Unknown",IF(OR(AND(ISNUMBER(I25),I25=0),AND(ISNUMBER(J25),J25<=EDATE('Scoring Settings'!$B$4,-'Scoring Settings'!$B$5))),"Not in use",IF(AND(ISNUMBER(I25),I25<'Scoring Settings'!$B$6),"Low use","Active")))) -> Low use | L25: 2 | M25: 4 | N25: Fiix | O25: On-prem DC | P25: dqiapp01, dqidb01 | Q25: 2 | R25: Windows Server 2008 | S25: SQL Server 2008 | T25: TBD | U25: 43655 | V25: Structured | W25: 160 | X25: N | Y25: 2 | Z25: Y | AA25: Archive + read-only | AB25: 3 | AC25: Partial | AD25: Partial | AE25: Y | AF25: 28500 | AG25: 47542 | AH25: 16000 | AI25: 22000 | AJ25: =IF(AND(ISNUMBER(AH25),ISNUMBER(AI25),N(AI25)>0),AH25/AI25*12,"") -> 8.7272727 | AK25: =IF(B25="","",OR(K25="Not in use",K25="Low use")+AND(N25<>"",N25<>"TBD")+AND(ISNUMBER(U25),U25<=EDATE('Scoring Settings'!$B$4,'Scoring Settings'!$B$8))+AND(ISNUMBER(L25),L25<='Scoring Settings'!$B$7)) -> 4 | AL25: Migrate | AM25: =IF(B25="","",IF(Z25="N","Easy",IF(OR(AND(ISNUMBER(AB25),AB25>'Scoring Settings'!$B$11),AND(ISNUMBER(W25),W25>'Scoring Settings'!$B$12),AND(ISNUMBER(M25),M25<='Scoring Settings'!$B$13)),"High","Medium"))) -> Medium | AN25: Wave 1 | AO25: 44500 | AP25: In progress | AQ25: Funding approved; migration to Fiix scheduled
A26: 18964 | B26: Custom Billing Engine | C26: Billing | D26: Finance | E26: External | I26: 0 | J26: 44251 | K26: =IF(B26="","",IF(AND(I26="",J26=""),"Unknown",IF(OR(AND(ISNUMBER(I26),I26=0),AND(ISNUMBER(J26),J26<=EDATE('Scoring Settings'!$B$4,-'Scoring Settings'!$B$5))),"Not in use",IF(AND(ISNUMBER(I26),I26<'Scoring Settings'!$B$6),"Low use","Active")))) -> Not in use | L26: 2 | M26: 4 | O26: IaaS | P26: cbeapp01, cbedb01, cbeweb01 | Q26: 3 | R26: Ubuntu 16.04 | S26: MySQL 5.7 | T26: Azure West Europe | U26: 44316 | V26: Structured | W26: 710 | X26: Y | Y26: 7 | Z26: N | AA26: None | AB26: 2 | AC26: Y | AD26: N | AE26: Partial | AF26: 32000 | AG26: 49582 | AH26: 30000 | AI26: 91000 | AJ26: =IF(AND(ISNUMBER(AH26),ISNUMBER(AI26),N(AI26)>0),AH26/AI26*12,"") -> 3.956044 | AK26: =IF(B26="","",OR(K26="Not in use",K26="Low use")+AND(N26<>"",N26<>"TBD")+AND(ISNUMBER(U26),U26<=EDATE('Scoring Settings'!$B$4,'Scoring Settings'!$B$8))+AND(ISNUMBER(L26),L26<='Scoring Settings'!$B$7)) -> 3 | AL26: Retire | AM26: =IF(B26="","",IF(Z26="N","Easy",IF(OR(AND(ISNUMBER(AB26),AB26>'Scoring Settings'!$B$11),AND(ISNUMBER(W26),W26>'Scoring Settings'!$B$12),AND(ISNUMBER(M26),M26<='Scoring Settings'!$B$13)),"High","Medium"))) -> Easy | AN26: Wave 1 | AO26: 44377 | AP26: In progress | AQ26: User comms sent; switch-off scheduled for end of May
A27: 23920 | B27: Departmental Budget Planner (FR) | C27: Budgeting | D27: Finance | E27: Internal | I27: 0 | J27: 44234 | K27: =IF(B27="","",IF(AND(I27="",J27=""),"Unknown",IF(OR(AND(ISNUMBER(I27),I27=0),AND(ISNUMBER(J27),J27<=EDATE('Scoring Settings'!$B$4,-'Scoring Settings'!$B$5))),"Not in use",IF(AND(ISNUMBER(I27),I27<'Scoring Settings'!$B$6),"Low use","Active")))) -> Not in use | L27: 3 | M27: 4 | O27: On-prem DC | P27: dbpapp01, dbpdb01 | Q27: 2 | R27: Windows Server 2008 | S27: SQL Server 2008 | T27: EU DC-2 | U27: 43655 | V27: Both | W27: 1100 | X27: Y | Y27: 7 | Z27: N | AA27: None | AB27: 2 | AC27: N | AD27: Y | AE27: Y | AF27: 45000 | AG27: 48152 | AH27: 35000 | AI27: 38000 | AJ27: =IF(AND(ISNUMBER(AH27),ISNUMBER(AI27),N(AI27)>0),AH27/AI27*12,"") -> 11.052632 | AK27: =IF(B27="","",OR(K27="Not in use",K27="Low use")+AND(N27<>"",N27<>"TBD")+AND(ISNUMBER(U27),U27<=EDATE('Scoring Settings'!$B$4,'Scoring Settings'!$B$8))+AND(ISNUMBER(L27),L27<='Scoring Settings'!$B$7)) -> 2 | AL27: Retire | AM27: =IF(B27="","",IF(Z27="N","Easy",IF(OR(AND(ISNUMBER(AB27),AB27>'Scoring Settings'!$B$11),AND(ISNUMBER(W27),W27>'Scoring Settings'!$B$12),AND(ISNUMBER(M27),M27<='Scoring Settings'!$B$13)),"High","Medium"))) -> Easy | AN27: Wave 1 | AO27: 44255 | AP27: Completed | AQ27: Switched off Feb-21; licence terminated
A28: 136942 | B28: Legacy Timesheet Portal (FR) | C28: Time & Attendance | D28: HR | E28: Internal | I28: 83 | J28: 44296 | K28: =IF(B28="","",IF(AND(I28="",J28=""),"Unknown",IF(OR(AND(ISNUMBER(I28),I28=0),AND(ISNUMBER(J28),J28<=EDATE('Scoring Settings'!$B$4,-'Scoring Settings'!$B$5))),"Not in use",IF(AND(ISNUMBER(I28),I28<'Scoring Settings'!$B$6),"Low use","Active")))) -> Active | L28: 1 | M28: 4 | N28: SuccessFactors | O28: On-prem DC | P28: ltpapp01, ltpdb01, ltpweb01 | Q28: 3 | R28: RHEL 6 | S28: Oracle 11g | T28: EU DC-1 | U28: 44165 | V28: Structured | W28: 3 | X28: Y | Y28: 7 | Z28: Y | AA28: Data archive | AB28: 2 | AC28: Y | AD28: Y | AE28: Partial | AF28: 33000 | AG28: 45991 | AH28: 35000 | AI28: 25500 | AJ28: =IF(AND(ISNUMBER(AH28),ISNUMBER(AI28),N(AI28)>0),AH28/AI28*12,"") -> 16.470588 | AK28: =IF(B28="","",OR(K28="Not in use",K28="Low use")+AND(N28<>"",N28<>"TBD")+AND(ISNUMBER(U28),U28<=EDATE('Scoring Settings'!$B$4,'Scoring Settings'!$B$8))+AND(ISNUMBER(L28),L28<='Scoring Settings'!$B$7)) -> 3 | AL28: Migrate | AM28: =IF(B28="","",IF(Z28="N","Easy",IF(OR(AND(ISNUMBER(AB28),AB28>'Scoring Settings'!$B$11),AND(ISNUMBER(W28),W28>'Scoring Settings'!$B$12),AND(ISNUMBER(M28),M28<='Scoring Settings'!$B$13)),"High","Medium"))) -> Medium | AN28: Wave 1 | AO28: 44408 | AP28: In progress | AQ28: 6 feeds to re-point to SuccessFactors
A29: 98378 | B29: Travel Booking Tool 2012 | C29: Travel | D29: HR | E29: Internal | I29: 317 | J29: 44308 | K29: =IF(B29="","",IF(AND(I29="",J29=""),"Unknown",IF(OR(AND(ISNUMBER(I29),I29=0),AND(ISNUMBER(J29),J29<=EDATE('Scoring Settings'!$B$4,-'Scoring Settings'!$B$5))),"Not in use",IF(AND(ISNUMBER(I29),I29<'Scoring Settings'!$B$6),"Low use","Active")))) -> Active | L29: 3 | M29: 4 | N29: Workday HCM | O29: On-prem DC | P29: tbtapp01, tbtdb01 | Q29: 2 | R29: Windows Server 2008 R2 | S29: SQL Server 2008 R2 | T29: US DC-1 | U29: 43844 | V29: Structured | W29: 62 | X29: Y | Y29: 7 | Z29: Y | AA29: Read-only access | AB29: 0 | AC29: N | AD29: N | AE29: N | AF29: 47500 | AG29: 46783 | AH29: 40000 | AI29: 33500 | AJ29: =IF(AND(ISNUMBER(AH29),ISNUMBER(AI29),N(AI29)>0),AH29/AI29*12,"") -> 14.328358 | AK29: =IF(B29="","",OR(K29="Not in use",K29="Low use")+AND(N29<>"",N29<>"TBD")+AND(ISNUMBER(U29),U29<=EDATE('Scoring Settings'!$B$4,'Scoring Settings'!$B$8))+AND(ISNUMBER(L29),L29<='Scoring Settings'!$B$7)) -> 2 | AL29: Migrate | AM29: =IF(B29="","",IF(Z29="N","Easy",IF(OR(AND(ISNUMBER(AB29),AB29>'Scoring Settings'!$B$11),AND(ISNUMBER(W29),W29>'Scoring Settings'!$B$12),AND(ISNUMBER(M29),M29<='Scoring Settings'!$B$13)),"High","Medium"))) -> Medium | AN29: Wave 1 | AO29: 44469 | AP29: In progress | AQ29: Cut-over planned for Sep-21; parallel run scheduled
A30: 84815 | B30: Shared Contract Repository (FR) | C30: Contract Mgmt | D30: Finance | E30: Partner | I30: 100 | J30: 44278 | K30: =IF(B30="","",IF(AND(I30="",J30=""),"Unknown",IF(OR(AND(ISNUMBER(I30),I30=0),AND(ISNUMBER(J30),J30<=EDATE('Scoring Settings'!$B$4,-'Scoring Settings'!$B$5))),"Not in use",IF(AND(ISNUMBER(I30),I30<'Scoring Settings'!$B$6),"Low use","Active")))) -> Active | L30: 3 | M30: 3 | O30: SaaS | P30: N/A (SaaS) | Q30: 0 | R30: N/A | S30: N/A | T30: Vendor cloud (EU) | U30: 46203 | V30: Both | W30: 93 | X30: Y | Y30: 7 | Z30: Y | AA30: Read-only access | AB30: 8 | AC30: Y | AD30: Partial | AE30: Partial | AF30: 31500 | AG30: 47118 | AH30: 32500 | AI30: 73000 | AJ30: =IF(AND(ISNUMBER(AH30),ISNUMBER(AI30),N(AI30)>0),AH30/AI30*12,"") -> 5.3424658 | AK30: =IF(B30="","",OR(K30="Not in use",K30="Low use")+AND(N30<>"",N30<>"TBD")+AND(ISNUMBER(U30),U30<=EDATE('Scoring Settings'!$B$4,'Scoring Settings'!$B$8))+AND(ISNUMBER(L30),L30<='Scoring Settings'!$B$7)) -> 0 | AL30: Retire + Archive | AM30: =IF(B30="","",IF(Z30="N","Easy",IF(OR(AND(ISNUMBER(AB30),AB30>'Scoring Settings'!$B$11),AND(ISNUMBER(W30),W30>'Scoring Settings'!$B$12),AND(ISNUMBER(M30),M30<='Scoring Settings'!$B$13)),"High","Medium"))) -> High | AN30: Wave 1 | AO30: 44347 | AP30: Completed | AQ30: Retention 7 yrs - archive slot booked
A31: 164470 | B31: Old Safety Incident Tracker Lite | C31: Health & Safety | D31: Operations | E31: Internal | I31: 0 | J31: 44250 | K31: =IF(B31="","",IF(AND(I31="",J31=""),"Unknown",IF(OR(AND(ISNUMBER(I31),I31=0),AND(ISNUMBER(J31),J31<=EDATE('Scoring Settings'!$B$4,-'Scoring Settings'!$B$5))),"Not in use",IF(AND(ISNUMBER(I31),I31<'Scoring Settings'!$B$6),"Low use","Active")))) -> Not in use | L31: 3 | M31: 3 | O31: On-prem DC | P31: osiapp01, osidb01, osiweb01 | Q31: 3 | R31: Ubuntu 16.04 | S31: MySQL 5.7 | T31: Plant DC | U31: 44316 | V31: Structured | W31: 200 | X31: N | Y31: 3 | Z31: N | AA31: None | AB31: 2 | AC31: Y | AD31: Y | AE31: Partial | AF31: 55000 | AG31: 47726 | AH31: 53500 | AI31: 54000 | AJ31: =IF(AND(ISNUMBER(AH31),ISNUMBER(AI31),N(AI31)>0),AH31/AI31*12,"") -> 11.888889 | AK31: =IF(B31="","",OR(K31="Not in use",K31="Low use")+AND(N31<>"",N31<>"TBD")+AND(ISNUMBER(U31),U31<=EDATE('Scoring Settings'!$B$4,'Scoring Settings'!$B$8))+AND(ISNUMBER(L31),L31<='Scoring Settings'!$B$7)) -> 2 | AL31: Retire | AM31: =IF(B31="","",IF(Z31="N","Easy",IF(OR(AND(ISNUMBER(AB31),AB31>'Scoring Settings'!$B$11),AND(ISNUMBER(W31),W31>'Scoring Settings'!$B$12),AND(ISNUMBER(M31),M31<='Scoring Settings'!$B$13)),"High","Medium"))) -> Easy | AN31: Wave 1 | AO31: 44255 | AP31: Completed | AQ31: Switched off Feb-21; licence terminated
A32: 65070 | B32: Payroll Interface (UK) | C32: Payroll | D32: HR | E32: Internal | I32: 0 | J32: 44241 | K32: =IF(B32="","",IF(AND(I32="",J32=""),"Unknown",IF(OR(AND(ISNUMBER(I32),I32=0),AND(ISNUMBER(J32),J32<=EDATE('Scoring Settings'!$B$4,-'Scoring Settings'!$B$5))),"Not in use",IF(AND(ISNUMBER(I32),I32<'Scoring Settings'!$B$6),"Low use","Active")))) -> Not in use | L32: 1 | M32: 4 | O32: SaaS | P32: N/A (SaaS) | Q32: 0 | R32: N/A | S32: N/A | T32: Vendor cloud (EU) | V32: Structured | W32: 180 | X32: Y | Y32: 5 | Z32: Y | AA32: Archive + read-only | AB32: 1 | AC32: Partial | AD32: Y | AE32: Partial | AF32: 42500 | AG32: 49552 | AH32: 53500 | AI32: 18500 | AJ32: =IF(AND(ISNUMBER(AH32),ISNUMBER(AI32),N(AI32)>0),AH32/AI32*12,"") -> 34.702703 | AK32: =IF(B32="","",OR(K32="Not in use",K32="Low use")+AND(N32<>"",N32<>"TBD")+AND(ISNUMBER(U32),U32<=EDATE('Scoring Settings'!$B$4,'Scoring Settings'!$B$8))+AND(ISNUMBER(L32),L32<='Scoring Settings'!$B$7)) -> 2 | AL32: Retire + Archive | AM32: =IF(B32="","",IF(Z32="N","Easy",IF(OR(AND(ISNUMBER(AB32),AB32>'Scoring Settings'!$B$11),AND(ISNUMBER(W32),W32>'Scoring Settings'!$B$12),AND(ISNUMBER(M32),M32<='Scoring Settings'!$B$13)),"High","Medium"))) -> Medium | AN32: Wave 1 | AO32: 44530 | AP32: In progress | AQ32: Read-only access needed for audit
A33: 97953 | B33: Shared Safety Incident Tracker | C33: Health & Safety | D33: Operations | E33: Internal | I33: 581 | J33: 44277 | K33: =IF(B33="","",IF(AND(I33="",J33=""),"Unknown",IF(OR(AND(ISNUMBER(I33),I33=0),AND(ISNUMBER(J33),J33<=EDATE('Scoring Settings'!$B$4,-'Scoring Settings'!$B$5))),"Not in use",IF(AND(ISNUMBER(I33),I33<'Scoring Settings'!$B$6),"Low use","Active")))) -> Active | L33: 4 | M33: 1 | N33: SAP EAM | O33: PaaS | P33: Azure App Service (PaaS) | Q33: 0 | R33: N/A (PaaS) | S33: Azure SQL | T33: Azure West Europe | U33: 44742 | V33: Structured | W33: 870 | X33: N | Y33: 7 | Z33: N | AA33: None | AB33: 60 | AC33: N | AD33: Partial | AE33: Y | AF33: 80000 | AG33: 48669 | AH33: 122000 | AI33: 49500 | AJ33: =IF(AND(ISNUMBER(AH33),ISNUMBER(AI33),N(AI33)>0),AH33/AI33*12,"") -> 29.575758 | AK33: =IF(B33="","",OR(K33="Not in use",K33="Low use")+AND(N33<>"",N33<>"TBD")+AND(ISNUMBER(U33),U33<=EDATE('Scoring Settings'!$B$4,'Scoring Settings'!$B$8))+AND(ISNUMBER(L33),L33<='Scoring Settings'!$B$7)) -> 1 | AL33: Migrate | AM33: =IF(B33="","",IF(Z33="N","Easy",IF(OR(AND(ISNUMBER(AB33),AB33>'Scoring Settings'!$B$11),AND(ISNUMBER(W33),W33>'Scoring Settings'!$B$12),AND(ISNUMBER(M33),M33<='Scoring Settings'!$B$13)),"High","Medium"))) -> Easy | AN33: Wave 1 | AO33: 44500 | AP33: In progress | AQ33: Funding approved; migration to SAP EAM scheduled
A34: 143504 | B34: Corporate Travel Booking Tool | C34: Travel | D34: HR | E34: Internal | I34: 96 | J34: 44277 | K34: =IF(B34="","",IF(AND(I34="",J34=""),"Unknown",IF(OR(AND(ISNUMBER(I34),I34=0),AND(ISNUMBER(J34),J34<=EDATE('Scoring Settings'!$B$4,-'Scoring Settings'!$B$5))),"Not in use",IF(AND(ISNUMBER(I34),I34<'Scoring Settings'!$B$6),"Low use","Active")))) -> Active | L34: 3 | M34: 3 | N34: Workday HCM (planned) | O34: On-prem DC | P34: fs-ctb02 (file share) | Q34: 1 | R34: Windows Server 2012 R2 | S34: MS Access 2010 | T34: Plant DC | U34: 45209 | V34: Both | W34: 89 | X34: Y | Y34: 10 | Z34: N | AA34: None | AB34: 1 | AC34: N | AD34: Partial | AE34: Y | AF34: 26000 | AG34: 47968 | AH34: 14500 | AI34: 78500 | AJ34: =IF(AND(ISNUMBER(AH34),ISNUMBER(AI34),N(AI34)>0),AH34/AI34*12,"") -> 2.2165605 | AK34: =IF(B34="","",OR(K34="Not in use",K34="Low use")+AND(N34<>"",N34<>"TBD")+AND(ISNUMBER(U34),U34<=EDATE('Scoring Settings'!$B$4,'Scoring Settings'!$B$8))+AND(ISNUMBER(L34),L34<='Scoring Settings'!$B$7)) -> 1 | AL34: Migrate | AM34: =IF(B34="","",IF(Z34="N","Easy",IF(OR(AND(ISNUMBER(AB34),AB34>'Scoring Settings'!$B$11),AND(ISNUMBER(W34),W34>'Scoring Settings'!$B$12),AND(ISNUMBER(M34),M34<='Scoring Settings'!$B$13)),"High","Medium"))) -> Easy | AN34: Wave 1 | AO34: 44500 | AP34: In progress | AQ34: Cut-over planned for Oct-21; parallel run scheduled
A35: 88761 | B35: Monitoring Console 2008 | C35: Monitoring | D35: IT | E35: Internal | I35: 10 | J35: 44310 | K35: =IF(B35="","",IF(AND(I35="",J35=""),"Unknown",IF(OR(AND(ISNUMBER(I35),I35=0),AND(ISNUMBER(J35),J35<=EDATE('Scoring Settings'!$B$4,-'Scoring Settings'!$B$5))),"Not in use",IF(AND(ISNUMBER(I35),I35<'Scoring Settings'!$B$6),"Low use","Active")))) -> Low use | L35: 1 | M35: 3 | N35: Microsoft 365 (planned) | O35: IaaS | P35: mcxapp01, mcxdb01 | Q35: 2 | R35: HP-UX 11i v3 | S35: TBD | T35: AWS us-east-1 | U35: 44561 | V35: Both | W35: 48 | X35: N | Y35: 7 | Z35: N | AA35: None | AB35: 5 | AC35: Partial | AD35: N | AE35: N | AF35: 16000 | AG35: 46507 | AH35: 6500 | AI35: 75000 | AJ35: =IF(AND(ISNUMBER(AH35),ISNUMBER(AI35),N(AI35)>0),AH35/AI35*12,"") -> 1.04 | AK35: =IF(B35="","",OR(K35="Not in use",K35="Low use")+AND(N35<>"",N35<>"TBD")+AND(ISNUMBER(U35),U35<=EDATE('Scoring Settings'!$B$4,'Scoring Settings'!$B$8))+AND(ISNUMBER(L35),L35<='Scoring Settings'!$B$7)) -> 4 | AL35: Retire | AM35: =IF(B35="","",IF(Z35="N","Easy",IF(OR(AND(ISNUMBER(AB35),AB35>'Scoring Settings'!$B$11),AND(ISNUMBER(W35),W35>'Scoring Settings'!$B$12),AND(ISNUMBER(M35),M35<='Scoring Settings'!$B$13)),"High","Medium"))) -> Easy | AN35: Wave 1 | AO35: 44347 | AP35: Completed | AQ35: No active users; switch-off confirmed with owner
A36: 145984 | B36: Departmental Safety Incident Tracker | C36: Health & Safety | D36: Operations | E36: Internal | I36: 4 | J36: 44263 | K36: =IF(B36="","",IF(AND(I36="",J36=""),"Unknown",IF(OR(AND(ISNUMBER(I36),I36=0),AND(ISNUMBER(J36),J36<=EDATE('Scoring Settings'!$B$4,-'Scoring Settings'!$B$5))),"Not in use",IF(AND(ISNUMBER(I36),I36<'Scoring Settings'!$B$6),"Low use","Active")))) -> Low use | L36: 2 | M36: 4 | N36: TBD | O36: On-prem DC | P36: dsiapp01 | Q36: 1 | R36: RHEL 6 | S36: Oracle 11g | T36: TBD | U36: 44165 | V36: Structured | W36: 8 | X36: N | Y36: 5 | Z36: N | AA36: None | AB36: 1 | AC36: Y | AD36: N | AE36: Y | AF36: 29500 | AG36: 47726 | AH36: 32000 | AI36: 88500 | AJ36: =IF(AND(ISNUMBER(AH36),ISNUMBER(AI36),N(AI36)>0),AH36/AI36*12,"") -> 4.3389831 | AK36: =IF(B36="","",OR(K36="Not in use",K36="Low use")+AND(N36<>"",N36<>"TBD")+AND(ISNUMBER(U36),U36<=EDATE('Scoring Settings'!$B$4,'Scoring Settings'!$B$8))+AND(ISNUMBER(L36),L36<='Scoring Settings'!$B$7)) -> 3 | AL36: Retire | AM36: =IF(B36="","",IF(Z36="N","Easy",IF(OR(AND(ISNUMBER(AB36),AB36>'Scoring Settings'!$B$11),AND(ISNUMBER(W36),W36>'Scoring Settings'!$B$12),AND(ISNUMBER(M36),M36<='Scoring Settings'!$B$13)),"High","Medium"))) -> Easy | AN36: Wave 1 | AO36: 44500 | AP36: In progress | AQ36: No active users; switch-off confirmed with owner
A37: 140092 | B37: Inventory Control Plus | C37: Inventory | D37: Supply Chain | E37: Internal | I37: 19 | J37: 44311 | K37: =IF(B37="","",IF(AND(I37="",J37=""),"Unknown",IF(OR(AND(ISNUMBER(I37),I37=0),AND(ISNUMBER(J37),J37<=EDATE('Scoring Settings'!$B$4,-'Scoring Settings'!$B$5))),"Not in use",IF(AND(ISNUMBER(I37),I37<'Scoring Settings'!$B$6),"Low use","Active")))) -> Low use | L37: 2 | M37: 4 | N37: TBD | O37: On-prem DC | P37: icpapp01, icpdb01 | Q37: 2 | R37: SUSE Linux 11 | S37: Oracle 11g | T37: EU DC-1 | U37: 43555 | V37: Structured | W37: 450 | X37: Y | Y37: 10 | Z37: Y | AA37: Archive + read-only | AB37: 3 | AC37: Partial | AD37: N | AE37: Partial | AF37: 31500 | AG37: 48273 | AH37: 30500 | AI37: 89000 | AJ37: =IF(AND(ISNUMBER(AH37),ISNUMBER(AI37),N(AI37)>0),AH37/AI37*12,"") -> 4.1123596 | AK37: =IF(B37="","",OR(K37="Not in use",K37="Low use")+AND(N37<>"",N37<>"TBD")+AND(ISNUMBER(U37),U37<=EDATE('Scoring Settings'!$B$4,'Scoring Settings'!$B$8))+AND(ISNUMBER(L37),L37<='Scoring Settings'!$B$7)) -> 3 | AL37: Retire + Archive | AM37: =IF(B37="","",IF(Z37="N","Easy",IF(OR(AND(ISNUMBER(AB37),AB37>'Scoring Settings'!$B$11),AND(ISNUMBER(W37),W37>'Scoring Settings'!$B$12),AND(ISNUMBER(M37),M37<='Scoring Settings'!$B$13)),"High","Medium"))) -> Medium | AN37: Wave 1 | AO37: 44530 | AP37: In progress | AQ37: Read-only access needed for audit
A38: 180343 | B38: Tax Compliance Tool (APAC) | C38: Tax | D38: Finance | E38: Internal | I38: 0 | J38: 44243 | K38: =IF(B38="","",IF(AND(I38="",J38=""),"Unknown",IF(OR(AND(ISNUMBER(I38),I38=0),AND(ISNUMBER(J38),J38<=EDATE('Scoring Settings'!$B$4,-'Scoring Settings'!$B$5))),"Not in use",IF(AND(ISNUMBER(I38),I38<'Scoring Settings'!$B$6),"Low use","Active")))) -> Not in use | L38: 1 | M38: 4 | O38: On-prem DC | P38: tctapp01, tctdb01, tctweb01 | Q38: 3 | R38: Windows Server 2008 R2 | S38: SQL Server 2008 R2 | T38: Plant DC | U38: 43844 | V38: Structured | W38: 13050 | X38: Y | Y38: 10 | Z38: Y | AA38: Data archive | AB38: 3 | AC38: N | AD38: N | AE38: Partial | AF38: 40500 | AG38: 48730 | AH38: 306500 | AI38: 63500 | AJ38: =IF(AND(ISNUMBER(AH38),ISNUMBER(AI38),N(AI38)>0),AH38/AI38*12,"") -> 57.92126 | AK38: =IF(B38="","",OR(K38="Not in use",K38="Low use")+AND(N38<>"",N38<>"TBD")+AND(ISNUMBER(U38),U38<=EDATE('Scoring Settings'!$B$4,'Scoring Settings'!$B$8))+AND(ISNUMBER(L38),L38<='Scoring Settings'!$B$7)) -> 3 | AL38: Retire + Archive | AM38: =IF(B38="","",IF(Z38="N","Easy",IF(OR(AND(ISNUMBER(AB38),AB38>'Scoring Settings'!$B$11),AND(ISNUMBER(W38),W38>'Scoring Settings'!$B$12),AND(ISNUMBER(M38),M38<='Scoring Settings'!$B$13)),"High","Medium"))) -> High | AN38: Wave 1 | AO38: 44255 | AP38: Completed | AQ38: Data archived and validated; switched off Feb-21
A39: 34980 | B39: Custom Org Chart Publisher (APAC) | C39: Org Mgmt | D39: HR | E39: Internal | I39: 11 | J39: 44229 | K39: =IF(B39="","",IF(AND(I39="",J39=""),"Unknown",IF(OR(AND(ISNUMBER(I39),I39=0),AND(ISNUMBER(J39),J39<=EDATE('Scoring Settings'!$B$4,-'Scoring Settings'!$B$5))),"Not in use",IF(AND(ISNUMBER(I39),I39<'Scoring Settings'!$B$6),"Low use","Active")))) -> Low use | L39: 2 | M39: 4 | N39: Workday Recruiting | O39: On-prem DC | P39: cocapp01, cocdb01, cocweb01 | Q39: 3 | R39: Ubuntu 16.04 | S39: MySQL 5.7 | T39: Plant DC | U39: 44316 | V39: Structured | W39: 1 | X39: Y | Y39: 7 | Z39: N | AA39: None | AB39: 3 | AC39: N | AD39: N | AE39: Y | AF39: 45500 | AG39: 46721 | AH39: 36000 | AI39: 55000 | AJ39: =IF(AND(ISNUMBER(AH39),ISNUMBER(AI39),N(AI39)>0),AH39/AI39*12,"") -> 7.8545455 | AK39: =IF(B39="","",OR(K39="Not in use",K39="Low use")+AND(N39<>"",N39<>"TBD")+AND(ISNUMBER(U39),U39<=EDATE('Scoring Settings'!$B$4,'Scoring Settings'!$B$8))+AND(ISNUMBER(L39),L39<='Scoring Settings'!$B$7)) -> 4 | AL39: Retire | AM39: =IF(B39="","",IF(Z39="N","Easy",IF(OR(AND(ISNUMBER(AB39),AB39>'Scoring Settings'!$B$11),AND(ISNUMBER(W39),W39>'Scoring Settings'!$B$12),AND(ISNUMBER(M39),M39<='Scoring Settings'!$B$13)),"High","Medium"))) -> Easy | AN39: Wave 1 | AO39: 44469 | AP39: In progress | AQ39: Functionality covered by existing tools
A40: 23345 | B40: Shared Inventory Control Classic | C40: Inventory | D40: Supply Chain | E40: Internal | I40: 7 | J40: 44209 | K40: =IF(B40="","",IF(AND(I40="",J40=""),"Unknown",IF(OR(AND(ISNUMBER(I40),I40=0),AND(ISNUMBER(J40),J40<=EDATE('Scoring Settings'!$B$4,-'Scoring Settings'!$B$5))),"Not in use",IF(AND(ISNUMBER(I40),I40<'Scoring Settings'!$B$6),"Low use","Active")))) -> Low use | L40: 1 | M40: 4 | O40: On-prem DC | P40: sicapp01 | Q40: 1 | R40: Windows Server 2016 | S40: SQL Server 2017 | T40: US DC-1 | U40: 46399 | V40: Both | W40: 180 | X40: Y | Y40: 10 | Z40: Y | AA40: Archive + read-only | AB40: 2 | AC40: Partial | AD40: Partial | AE40: Partial | AF40: 11500 | AG40: 47603 | AH40: 14000 | AI40: 68500 | AJ40: =IF(AND(ISNUMBER(AH40),ISNUMBER(AI40),N(AI40)>0),AH40/AI40*12,"") -> 2.4525547 | AK40: =IF(B40="","",OR(K40="Not in use",K40="Low use")+AND(N40<>"",N40<>"TBD")+AND(ISNUMBER(U40),U40<=EDATE('Scoring Settings'!$B$4,'Scoring Settings'!$B$8))+AND(ISNUMBER(L40),L40<='Scoring Settings'!$B$7)) -> 2 | AL40: Retire + Archive | AM40: =IF(B40="","",IF(Z40="N","Easy",IF(OR(AND(ISNUMBER(AB40),AB40>'Scoring Settings'!$B$11),AND(ISNUMBER(W40),W40>'Scoring Settings'!$B$12),AND(ISNUMBER(M40),M40<='Scoring Settings'!$B$13)),"High","Medium"))) -> Medium | AN40: Wave 1 | AO40: 44530 | AP40: In progress | AQ40: Retention 10 yrs - archive slot booked
...

Sheet Summary
A1: Decommissioning Summary
A2: All figures formula-driven from the Application Inventory tab.
A3: Current Wave | B3: Wave 1
A4: Status As On | B4: 44317
A5: Total applications | B5: =COUNTA('Application Inventory'!$B$5:$B$1004) -> 1000
A6: Applications with a decision (in plan) | B6: =COUNTIF('Application Inventory'!$AL$5:$AL$1004,"Decommission")+COUNTIF('Application Inventory'!$AL$5:$AL$1004,"Retire")+COUNTIF('Application Inventory'!$AL$5:$AL$1004,"Retire + Archive")+COUNTIF('Application Inventory'!$AL$5:$AL$1004,"Retain") -> 549
A7: Change candidates (Decommission / Retire / Retire + Archive) | B7: =COUNTIF('Application Inventory'!$AL$5:$AL$1004,"Decommission")+COUNTIF('Application Inventory'!$AL$5:$AL$1004,"Retire")+COUNTIF('Application Inventory'!$AL$5:$AL$1004,"Retire + Archive") -> 349
A8: Retain | B8: =COUNTIF('Application Inventory'!$AL$5:$AL$1004,"Retain") -> 200
A9: Pending decision | B9: =COUNTIF('Application Inventory'!$AL$5:$AL$1004,"Pending") -> 300
A10: Annual savings from change candidates ($) | B10: =SUMIF('Application Inventory'!$AL$5:$AL$1004,"Decommission",'Application Inventory'!$AI$5:$AI$1004)+SUMIF('Application Inventory'!$AL$5:$AL$1004,"Retire",'Application Inventory'!$AI$5:$AI$1004)+SUMIF('Application Inventory'!$AL$5:$AL$1004,"Retire + Archive",'Application Inventory'!$AI$5:$AI$1004) -> 12956000
A11: Completed to date (target retirement before May 2021) | B11: =COUNTIF('Application Inventory'!$AP$5:$AP$1004,"Completed") -> 58
A12: Decision | B12: Easy | C12: Medium | D12: High | E12: Total | F12: Annual Run Cost ($) | G12: Annual Savings ($) | H12: Est. Decom Cost ($) | I12: Data Volume (GB)
A13: Decommission | B13: =COUNTIFS('Application Inventory'!$AL$5:$AL$1004,$A13,'Application Inventory'!$AM$5:$AM$1004,"Easy") -> 0 | C13: =COUNTIFS('Application Inventory'!$AL$5:$AL$1004,$A13,'Application Inventory'!$AM$5:$AM$1004,"Medium") -> 0 | D13: =COUNTIFS('Application Inventory'!$AL$5:$AL$1004,$A13,'Application Inventory'!$AM$5:$AM$1004,"High") -> 0 | E13: =SUM(B13:D13) -> 0 | F13: =SUMIF('Application Inventory'!$AL$5:$AL$1004,$A13,'Application Inventory'!$AF$5:$AF$1004) -> 0 | G13: =SUMIF('Application Inventory'!$AL$5:$AL$1004,$A13,'Application Inventory'!$AI$5:$AI$1004) -> 0 | H13: =SUMIF('Application Inventory'!$AL$5:$AL$1004,$A13,'Application Inventory'!$AH$5:$AH$1004) -> 0 | I13: =SUMIF('Application Inventory'!$AL$5:$AL$1004,$A13,'Application Inventory'!$W$5:$W$1004) -> 0
A14: Retire | B14: =COUNTIFS('Application Inventory'!$AL$5:$AL$1004,$A14,'Application Inventory'!$AM$5:$AM$1004,"Easy") -> 161 | C14: =COUNTIFS('Application Inventory'!$AL$5:$AL$1004,$A14,'Application Inventory'!$AM$5:$AM$1004,"Medium") -> 0 | D14: =COUNTIFS('Application Inventory'!$AL$5:$AL$1004,$A14,'Application Inventory'!$AM$5:$AM$1004,"High") -> 0 | E14: =SUM(B14:D14) -> 161 | F14: =SUMIF('Application Inventory'!$AL$5:$AL$1004,$A14,'Application Inventory'!$AF$5:$AF$1004) -> 7969500 | G14: =SUMIF('Application Inventory'!$AL$5:$AL$1004,$A14,'Application Inventory'!$AI$5:$AI$1004) -> 6950000 | H14: =SUMIF('Application Inventory'!$AL$5:$AL$1004,$A14,'Application Inventory'!$AH$5:$AH$1004) -> 39038000 | I14: =SUMIF('Application Inventory'!$AL$5:$AL$1004,$A14,'Application Inventory'!$W$5:$W$1004) -> 53027
A15: Retire + Archive | B15: =COUNTIFS('Application Inventory'!$AL$5:$AL$1004,$A15,'Application Inventory'!$AM$5:$AM$1004,"Easy") -> 0 | C15: =COUNTIFS('Application Inventory'!$AL$5:$AL$1004,$A15,'Application Inventory'!$AM$5:$AM$1004,"Medium") -> 105 | D15: =COUNTIFS('Application Inventory'!$AL$5:$AL$1004,$A15,'Application Inventory'!$AM$5:$AM$1004,"High") -> 83 | E15: =SUM(B15:D15) -> 188 | F15: =SUMIF('Application Inventory'!$AL$5:$AL$1004,$A15,'Application Inventory'!$AF$5:$AF$1004) -> 9228000 | G15: =SUMIF('Application Inventory'!$AL$5:$AL$1004,$A15,'Application Inventory'!$AI$5:$AI$1004) -> 6006000 | H15: =SUMIF('Application Inventory'!$AL$5:$AL$1004,$A15,'Application Inventory'!$AH$5:$AH$1004) -> 13290500 | I15: =SUMIF('Application Inventory'!$AL$5:$AL$1004,$A15,'Application Inventory'!$W$5:$W$1004) -> 184467
A16: Retain | B16: =COUNTIFS('Application Inventory'!$AL$5:$AL$1004,$A16,'Application Inventory'!$AM$5:$AM$1004,"Easy") -> 83 | C16: =COUNTIFS('Application Inventory'!$AL$5:$AL$1004,$A16,'Application Inventory'!$AM$5:$AM$1004,"Medium") -> 18 | D16: =COUNTIFS('Application Inventory'!$AL$5:$AL$1004,$A16,'Application Inventory'!$AM$5:$AM$1004,"High") -> 99 | E16: =SUM(B16:D16) -> 200 | F16: =SUMIF('Application Inventory'!$AL$5:$AL$1004,$A16,'Application Inventory'!$AF$5:$AF$1004) -> 19221500 | G16: =SUMIF('Application Inventory'!$AL$5:$AL$1004,$A16,'Application Inventory'!$AI$5:$AI$1004) -> 0 | H16: =SUMIF('Application Inventory'!$AL$5:$AL$1004,$A16,'Application Inventory'!$AH$5:$AH$1004) -> 0 | I16: =SUMIF('Application Inventory'!$AL$5:$AL$1004,$A16,'Application Inventory'!$W$5:$W$1004) -> 104569
A17: Total | B17: =SUM(B13:B16) -> 244 | C17: =SUM(C13:C16) -> 123 | D17: =SUM(D13:D16) -> 182 | E17: =SUM(E13:E16) -> 549 | F17: =SUM(F13:F16) -> 36419000 | G17: =SUM(G13:G16) -> 12956000 | H17: =SUM(H13:H16) -> 52328500 | I17: =SUM(I13:I16) -> 342063
A19: Wave | B19: # Apps | C19: Annual Savings ($) | D19: Est. Decom Cost ($)
A20: Wave 1 | B20: =COUNTIF('Application Inventory'!$AN$5:$AN$1004,A20) -> 145 | C20: =SUMIF('Application Inventory'!$AN$5:$AN$1004,A20,'Application Inventory'!$AI$5:$AI$1004) -> 7647500 | D20: =SUMIF('Application Inventory'!$AN$5:$AN$1004,A20,'Application Inventory'!$AH$5:$AH$1004) -> 40835500
A21: Wave 2 | B21: =COUNTIF('Application Inventory'!$AN$5:$AN$1004,A21) -> 190 | C21: =SUMIF('Application Inventory'!$AN$5:$AN$1004,A21,'Application Inventory'!$AI$5:$AI$1004) -> 6919000 | D21: =SUMIF('Application Inventory'!$AN$5:$AN$1004,A21,'Application Inventory'!$AH$5:$AH$1004) -> 14090000
A22: Wave 3 | B22: =COUNTIF('Application Inventory'!$AN$5:$AN$1004,A22) -> 165 | C22: =SUMIF('Application Inventory'!$AN$5:$AN$1004,A22,'Application Inventory'!$AI$5:$AI$1004) -> 7503500 | D22: =SUMIF('Application Inventory'!$AN$5:$AN$1004,A22,'Application Inventory'!$AH$5:$AH$1004) -> 18336000
A23: Backlog | B23: =COUNTIF('Application Inventory'!$AN$5:$AN$1004,A23) -> 0 | C23: =SUMIF('Application Inventory'!$AN$5:$AN$1004,A23,'Application Inventory'!$AI$5:$AI$1004) -> 0 | D23: =SUMIF('Application Inventory'!$AN$5:$AN$1004,A23,'Application Inventory'!$AH$5:$AH$1004) -> 0
A25: Status | B25: # Apps
A26: Under Review | B26: =COUNTIF('Application Inventory'!$AP$5:$AP$1004,A26) -> 547
A27: Approved | B27: =COUNTIF('Application Inventory'!$AP$5:$AP$1004,A27) -> 152
A28: In progress | B28: =COUNTIF('Application Inventory'!$AP$5:$AP$1004,A28) -> 65
A29: On hold | B29: =COUNTIF('Application Inventory'!$AP$5:$AP$1004,A29) -> 4
A30: Completed | B30: =COUNTIF('Application Inventory'!$AP$5:$AP$1004,A30) -> 58
A31: Rejected | B31: =COUNTIF('Application Inventory'!$AP$5:$AP$1004,A31) -> 174
I32: Select Wave | J32: Wave 1
I33: Complexity | J33: (All)
A34: Planned retirements by month (formula-driven from Target Retirement Date and Decision)
A35: Target retirement period | B35: Migrate | C35: Retire | D35: Retire + Archive | E35: Total | F35: From | G35: To | I35: Count of App ID | J35: Column Labels
A36: Jan 2021 | B36: =COUNTIFS('Application Inventory'!$AL$5:$AL$1004,"Migrate",'Application Inventory'!$AO$5:$AO$1004,">="&$F36,'Application Inventory'!$AO$5:$AO$1004,"<="&$G36) -> 1 | C36: =COUNTIFS('Application Inventory'!$AL$5:$AL$1004,"Retire",'Application Inventory'!$AO$5:$AO$1004,">="&$F36,'Application Inventory'!$AO$5:$AO$1004,"<="&$G36) -> 4 | D36: =COUNTIFS('Application Inventory'!$AL$5:$AL$1004,"Retire + Archive",'Application Inventory'!$AO$5:$AO$1004,">="&$F36,'Application Inventory'!$AO$5:$AO$1004,"<="&$G36) -> 3 | E36: =SUM(B36:D36) -> 8 | F36: 44197 | G36: 44227 | I36: Row Labels | J36: 44227 | K36: 44255 | L36: 44286 | M36: 44316 | N36: 44347 | O36: 44377 | P36: 44408 | Q36: 44439 | R36: 44469 | S36: 44500 | T36: 44530 | U36: 44561 | V36: Grand Total
A37: Feb 2021 | B37: =COUNTIFS('Application Inventory'!$AL$5:$AL$1004,"Migrate",'Application Inventory'!$AO$5:$AO$1004,">="&$F37,'Application Inventory'!$AO$5:$AO$1004,"<="&$G37) -> 2 | C37: =COUNTIFS('Application Inventory'!$AL$5:$AL$1004,"Retire",'Application Inventory'!$AO$5:$AO$1004,">="&$F37,'Application Inventory'!$AO$5:$AO$1004,"<="&$G37) -> 3 | D37: =COUNTIFS('Application Inventory'!$AL$5:$AL$1004,"Retire + Archive",'Application Inventory'!$AO$5:$AO$1004,">="&$F37,'Application Inventory'!$AO$5:$AO$1004,"<="&$G37) -> 5 | E37: =SUM(B37:D37) -> 10 | F37: 44228 | G37: 44255 | I37: Approved | Q37: 2 | R37: 1 | S37: 2 | T37: 2 | U37: 11 | V37: 18
